2022-04-01 10:20:11 [ERROR] : 提交变更失败
Traceback (most recent call last):
  File "/root/project/threat-broadcast-1/src/utils/_git.py", line 26, in auto_commit
    repo.git.push()
  File "/usr/local/python3/lib/python3.8/site-packages/git/cmd.py", line 542, in <lambda>
    return lambda *args, **kwargs: self._call_process(name, *args, **kwargs)
  File "/usr/local/python3/lib/python3.8/site-packages/git/cmd.py", line 1005, in _call_process
    return self.execute(call, **exec_kwargs)
  File "/usr/local/python3/lib/python3.8/site-packages/git/cmd.py", line 822, in execute
    raise GitCommandError(command, status, stderr_value, stdout_value)
git.exc.GitCommandError: Cmd('git') failed due to: exit code(1)
  cmdline: git push
  stderr: 'To git@github.com:hkmayfly/threat-broadcast-1.git
 ! [rejected]        master -> master (fetch first)
error: failed to push some refs to 'git@github.com:hkmayfly/threat-broadcast-1.git'
hint: Updates were rejected because the remote contains work that you do
hint: not have locally. This is usually caused by another repository pushing
hint: to the same ref. You may want to first merge the remote changes (e.g.,
hint: 'git pull') before pushing again.
hint: See the 'Note about fast-forwards' in 'git push --help' for details.'
2022-04-01 10:20:11 [ERROR] : Traceback (most recent call last):
  File "/root/project/threat-broadcast-1/src/utils/_git.py", line 26, in auto_commit
    repo.git.push()
  File "/usr/local/python3/lib/python3.8/site-packages/git/cmd.py", line 542, in <lambda>
    return lambda *args, **kwargs: self._call_process(name, *args, **kwargs)
  File "/usr/local/python3/lib/python3.8/site-packages/git/cmd.py", line 1005, in _call_process
    return self.execute(call, **exec_kwargs)
  File "/usr/local/python3/lib/python3.8/site-packages/git/cmd.py", line 822, in execute
    raise GitCommandError(command, status, stderr_value, stdout_value)
git.exc.GitCommandError: Cmd('git') failed due to: exit code(1)
  cmdline: git push
  stderr: 'To git@github.com:hkmayfly/threat-broadcast-1.git
 ! [rejected]        master -> master (fetch first)
error: failed to push some refs to 'git@github.com:hkmayfly/threat-broadcast-1.git'
hint: Updates were rejected because the remote contains work that you do
hint: not have locally. This is usually caused by another repository pushing
hint: to the same ref. You may want to first merge the remote changes (e.g.,
hint: 'git pull') before pushing again.
hint: See the 'Note about fast-forwards' in 'git push --help' for details.'
Traceback (most recent call last):
  File "/root/project/threat-broadcast-1/src/utils/_git.py", line 26, in auto_commit
    repo.git.push()
  File "/usr/local/python3/lib/python3.8/site-packages/git/cmd.py", line 542, in <lambda>
    return lambda *args, **kwargs: self._call_process(name, *args, **kwargs)
  File "/usr/local/python3/lib/python3.8/site-packages/git/cmd.py", line 1005, in _call_process
    return self.execute(call, **exec_kwargs)
  File "/usr/local/python3/lib/python3.8/site-packages/git/cmd.py", line 822, in execute
    raise GitCommandError(command, status, stderr_value, stdout_value)
git.exc.GitCommandError: Cmd('git') failed due to: exit code(1)
  cmdline: git push
  stderr: 'To git@github.com:hkmayfly/threat-broadcast-1.git
 ! [rejected]        master -> master (fetch first)
error: failed to push some refs to 'git@github.com:hkmayfly/threat-broadcast-1.git'
hint: Updates were rejected because the remote contains work that you do
hint: not have locally. This is usually caused by another repository pushing
hint: to the same ref. You may want to first merge the remote changes (e.g.,
hint: 'git pull') before pushing again.
hint: See the 'Note about fast-forwards' in 'git push --help' for details.'
2022-04-01 10:23:06 [ERROR] : 提交变更失败
Traceback (most recent call last):
  File "/root/project/threat-broadcast-1/src/utils/_git.py", line 26, in auto_commit
    repo.git.push()
  File "/usr/local/python3/lib/python3.8/site-packages/git/cmd.py", line 542, in <lambda>
    return lambda *args, **kwargs: self._call_process(name, *args, **kwargs)
  File "/usr/local/python3/lib/python3.8/site-packages/git/cmd.py", line 1005, in _call_process
    return self.execute(call, **exec_kwargs)
  File "/usr/local/python3/lib/python3.8/site-packages/git/cmd.py", line 822, in execute
    raise GitCommandError(command, status, stderr_value, stdout_value)
git.exc.GitCommandError: Cmd('git') failed due to: exit code(1)
  cmdline: git push
  stderr: 'To git@github.com:hkmayfly/threat-broadcast-1.git
 ! [rejected]        master -> master (fetch first)
error: failed to push some refs to 'git@github.com:hkmayfly/threat-broadcast-1.git'
hint: Updates were rejected because the remote contains work that you do
hint: not have locally. This is usually caused by another repository pushing
hint: to the same ref. You may want to first merge the remote changes (e.g.,
hint: 'git pull') before pushing again.
hint: See the 'Note about fast-forwards' in 'git push --help' for details.'
2022-04-01 10:23:06 [ERROR] : Traceback (most recent call last):
  File "/root/project/threat-broadcast-1/src/utils/_git.py", line 26, in auto_commit
    repo.git.push()
  File "/usr/local/python3/lib/python3.8/site-packages/git/cmd.py", line 542, in <lambda>
    return lambda *args, **kwargs: self._call_process(name, *args, **kwargs)
  File "/usr/local/python3/lib/python3.8/site-packages/git/cmd.py", line 1005, in _call_process
    return self.execute(call, **exec_kwargs)
  File "/usr/local/python3/lib/python3.8/site-packages/git/cmd.py", line 822, in execute
    raise GitCommandError(command, status, stderr_value, stdout_value)
git.exc.GitCommandError: Cmd('git') failed due to: exit code(1)
  cmdline: git push
  stderr: 'To git@github.com:hkmayfly/threat-broadcast-1.git
 ! [rejected]        master -> master (fetch first)
error: failed to push some refs to 'git@github.com:hkmayfly/threat-broadcast-1.git'
hint: Updates were rejected because the remote contains work that you do
hint: not have locally. This is usually caused by another repository pushing
hint: to the same ref. You may want to first merge the remote changes (e.g.,
hint: 'git pull') before pushing again.
hint: See the 'Note about fast-forwards' in 'git push --help' for details.'
Traceback (most recent call last):
  File "/root/project/threat-broadcast-1/src/utils/_git.py", line 26, in auto_commit
    repo.git.push()
  File "/usr/local/python3/lib/python3.8/site-packages/git/cmd.py", line 542, in <lambda>
    return lambda *args, **kwargs: self._call_process(name, *args, **kwargs)
  File "/usr/local/python3/lib/python3.8/site-packages/git/cmd.py", line 1005, in _call_process
    return self.execute(call, **exec_kwargs)
  File "/usr/local/python3/lib/python3.8/site-packages/git/cmd.py", line 822, in execute
    raise GitCommandError(command, status, stderr_value, stdout_value)
git.exc.GitCommandError: Cmd('git') failed due to: exit code(1)
  cmdline: git push
  stderr: 'To git@github.com:hkmayfly/threat-broadcast-1.git
 ! [rejected]        master -> master (fetch first)
error: failed to push some refs to 'git@github.com:hkmayfly/threat-broadcast-1.git'
hint: Updates were rejected because the remote contains work that you do
hint: not have locally. This is usually caused by another repository pushing
hint: to the same ref. You may want to first merge the remote changes (e.g.,
hint: 'git pull') before pushing again.
hint: See the 'Note about fast-forwards' in 'git push --help' for details.'
2022-04-01 14:51:55 [ERROR] : 获取 [360 网络安全响应中心] 威胁情报异常
Traceback (most recent call last):
  File "/opt/hostedtoolcache/Python/3.8.12/x64/lib/python3.8/site-packages/urllib3/connectionpool.py", line 670, in urlopen
    httplib_response = self._make_request(
  File "/opt/hostedtoolcache/Python/3.8.12/x64/lib/python3.8/site-packages/urllib3/connectionpool.py", line 381, in _make_request
    self._validate_conn(conn)
  File "/opt/hostedtoolcache/Python/3.8.12/x64/lib/python3.8/site-packages/urllib3/connectionpool.py", line 978, in _validate_conn
    conn.connect()
  File "/opt/hostedtoolcache/Python/3.8.12/x64/lib/python3.8/site-packages/urllib3/connection.py", line 362, in connect
    self.sock = ssl_wrap_socket(
  File "/opt/hostedtoolcache/Python/3.8.12/x64/lib/python3.8/site-packages/urllib3/util/ssl_.py", line 386, in ssl_wrap_socket
    return context.wrap_socket(sock, server_hostname=server_hostname)
  File "/opt/hostedtoolcache/Python/3.8.12/x64/lib/python3.8/ssl.py", line 500, in wrap_socket
    return self.sslsocket_class._create(
  File "/opt/hostedtoolcache/Python/3.8.12/x64/lib/python3.8/ssl.py", line 1040, in _create
    self.do_handshake()
  File "/opt/hostedtoolcache/Python/3.8.12/x64/lib/python3.8/ssl.py", line 1309, in do_handshake
    self._sslobj.do_handshake()
ssl.SSLEOFError: EOF occurred in violation of protocol (_ssl.c:1131)

During handling of the above exception, another exception occurred:

Traceback (most recent call last):
  File "/opt/hostedtoolcache/Python/3.8.12/x64/lib/python3.8/site-packages/requests/adapters.py", line 439, in send
    resp = conn.urlopen(
  File "/opt/hostedtoolcache/Python/3.8.12/x64/lib/python3.8/site-packages/urllib3/connectionpool.py", line 726, in urlopen
    retries = retries.increment(
  File "/opt/hostedtoolcache/Python/3.8.12/x64/lib/python3.8/site-packages/urllib3/util/retry.py", line 446, in increment
    raise MaxRetryError(_pool, url, error or ResponseError(cause))
urllib3.exceptions.MaxRetryError: HTTPSConnectionPool(host='cert.360.cn', port=443): Max retries exceeded with url: /warning/searchbypage?length=6&start=0 (Caused by SSLError(SSLEOFError(8, 'EOF occurred in violation of protocol (_ssl.c:1131)')))

During handling of the above exception, another exception occurred:

Traceback (most recent call last):
  File "/home/runner/work/threat-broadcast-1/threat-broadcast-1/src/crawler/_base_crawler.py", line 62, in cves
    new_cves = self.get_cves()
  File "/home/runner/work/threat-broadcast-1/threat-broadcast-1/src/crawler/cert360.py", line 48, in get_cves
    response = requests.get(
  File "/opt/hostedtoolcache/Python/3.8.12/x64/lib/python3.8/site-packages/requests/api.py", line 75, in get
    return request('get', url, params=params, **kwargs)
  File "/opt/hostedtoolcache/Python/3.8.12/x64/lib/python3.8/site-packages/requests/api.py", line 60, in request
    return session.request(method=method, url=url, **kwargs)
  File "/opt/hostedtoolcache/Python/3.8.12/x64/lib/python3.8/site-packages/requests/sessions.py", line 533, in request
    resp = self.send(prep, **send_kwargs)
  File "/opt/hostedtoolcache/Python/3.8.12/x64/lib/python3.8/site-packages/requests/sessions.py", line 646, in send
    r = adapter.send(request, **kwargs)
  File "/opt/hostedtoolcache/Python/3.8.12/x64/lib/python3.8/site-packages/requests/adapters.py", line 514, in send
    raise SSLError(e, request=request)
requests.exceptions.SSLError: HTTPSConnectionPool(host='cert.360.cn', port=443): Max retries exceeded with url: /warning/searchbypage?length=6&start=0 (Caused by SSLError(SSLEOFError(8, 'EOF occurred in violation of protocol (_ssl.c:1131)')))
2022-04-01 14:51:55 [ERROR] : Traceback (most recent call last):
  File "/opt/hostedtoolcache/Python/3.8.12/x64/lib/python3.8/site-packages/urllib3/connectionpool.py", line 670, in urlopen
    httplib_response = self._make_request(
  File "/opt/hostedtoolcache/Python/3.8.12/x64/lib/python3.8/site-packages/urllib3/connectionpool.py", line 381, in _make_request
    self._validate_conn(conn)
  File "/opt/hostedtoolcache/Python/3.8.12/x64/lib/python3.8/site-packages/urllib3/connectionpool.py", line 978, in _validate_conn
    conn.connect()
  File "/opt/hostedtoolcache/Python/3.8.12/x64/lib/python3.8/site-packages/urllib3/connection.py", line 362, in connect
    self.sock = ssl_wrap_socket(
  File "/opt/hostedtoolcache/Python/3.8.12/x64/lib/python3.8/site-packages/urllib3/util/ssl_.py", line 386, in ssl_wrap_socket
    return context.wrap_socket(sock, server_hostname=server_hostname)
  File "/opt/hostedtoolcache/Python/3.8.12/x64/lib/python3.8/ssl.py", line 500, in wrap_socket
    return self.sslsocket_class._create(
  File "/opt/hostedtoolcache/Python/3.8.12/x64/lib/python3.8/ssl.py", line 1040, in _create
    self.do_handshake()
  File "/opt/hostedtoolcache/Python/3.8.12/x64/lib/python3.8/ssl.py", line 1309, in do_handshake
    self._sslobj.do_handshake()
ssl.SSLEOFError: EOF occurred in violation of protocol (_ssl.c:1131)

During handling of the above exception, another exception occurred:

Traceback (most recent call last):
  File "/opt/hostedtoolcache/Python/3.8.12/x64/lib/python3.8/site-packages/requests/adapters.py", line 439, in send
    resp = conn.urlopen(
  File "/opt/hostedtoolcache/Python/3.8.12/x64/lib/python3.8/site-packages/urllib3/connectionpool.py", line 726, in urlopen
    retries = retries.increment(
  File "/opt/hostedtoolcache/Python/3.8.12/x64/lib/python3.8/site-packages/urllib3/util/retry.py", line 446, in increment
    raise MaxRetryError(_pool, url, error or ResponseError(cause))
urllib3.exceptions.MaxRetryError: HTTPSConnectionPool(host='cert.360.cn', port=443): Max retries exceeded with url: /warning/searchbypage?length=6&start=0 (Caused by SSLError(SSLEOFError(8, 'EOF occurred in violation of protocol (_ssl.c:1131)')))

During handling of the above exception, another exception occurred:

Traceback (most recent call last):
  File "/home/runner/work/threat-broadcast-1/threat-broadcast-1/src/crawler/_base_crawler.py", line 62, in cves
    new_cves = self.get_cves()
  File "/home/runner/work/threat-broadcast-1/threat-broadcast-1/src/crawler/cert360.py", line 48, in get_cves
    response = requests.get(
  File "/opt/hostedtoolcache/Python/3.8.12/x64/lib/python3.8/site-packages/requests/api.py", line 75, in get
    return request('get', url, params=params, **kwargs)
  File "/opt/hostedtoolcache/Python/3.8.12/x64/lib/python3.8/site-packages/requests/api.py", line 60, in request
    return session.request(method=method, url=url, **kwargs)
  File "/opt/hostedtoolcache/Python/3.8.12/x64/lib/python3.8/site-packages/requests/sessions.py", line 533, in request
    resp = self.send(prep, **send_kwargs)
  File "/opt/hostedtoolcache/Python/3.8.12/x64/lib/python3.8/site-packages/requests/sessions.py", line 646, in send
    r = adapter.send(request, **kwargs)
  File "/opt/hostedtoolcache/Python/3.8.12/x64/lib/python3.8/site-packages/requests/adapters.py", line 514, in send
    raise SSLError(e, request=request)
requests.exceptions.SSLError: HTTPSConnectionPool(host='cert.360.cn', port=443): Max retries exceeded with url: /warning/searchbypage?length=6&start=0 (Caused by SSLError(SSLEOFError(8, 'EOF occurred in violation of protocol (_ssl.c:1131)')))
Traceback (most recent call last):
  File "/opt/hostedtoolcache/Python/3.8.12/x64/lib/python3.8/site-packages/urllib3/connectionpool.py", line 670, in urlopen
    httplib_response = self._make_request(
  File "/opt/hostedtoolcache/Python/3.8.12/x64/lib/python3.8/site-packages/urllib3/connectionpool.py", line 381, in _make_request
    self._validate_conn(conn)
  File "/opt/hostedtoolcache/Python/3.8.12/x64/lib/python3.8/site-packages/urllib3/connectionpool.py", line 978, in _validate_conn
    conn.connect()
  File "/opt/hostedtoolcache/Python/3.8.12/x64/lib/python3.8/site-packages/urllib3/connection.py", line 362, in connect
    self.sock = ssl_wrap_socket(
  File "/opt/hostedtoolcache/Python/3.8.12/x64/lib/python3.8/site-packages/urllib3/util/ssl_.py", line 386, in ssl_wrap_socket
    return context.wrap_socket(sock, server_hostname=server_hostname)
  File "/opt/hostedtoolcache/Python/3.8.12/x64/lib/python3.8/ssl.py", line 500, in wrap_socket
    return self.sslsocket_class._create(
  File "/opt/hostedtoolcache/Python/3.8.12/x64/lib/python3.8/ssl.py", line 1040, in _create
    self.do_handshake()
  File "/opt/hostedtoolcache/Python/3.8.12/x64/lib/python3.8/ssl.py", line 1309, in do_handshake
    self._sslobj.do_handshake()
ssl.SSLEOFError: EOF occurred in violation of protocol (_ssl.c:1131)

During handling of the above exception, another exception occurred:

Traceback (most recent call last):
  File "/opt/hostedtoolcache/Python/3.8.12/x64/lib/python3.8/site-packages/requests/adapters.py", line 439, in send
    resp = conn.urlopen(
  File "/opt/hostedtoolcache/Python/3.8.12/x64/lib/python3.8/site-packages/urllib3/connectionpool.py", line 726, in urlopen
    retries = retries.increment(
  File "/opt/hostedtoolcache/Python/3.8.12/x64/lib/python3.8/site-packages/urllib3/util/retry.py", line 446, in increment
    raise MaxRetryError(_pool, url, error or ResponseError(cause))
urllib3.exceptions.MaxRetryError: HTTPSConnectionPool(host='cert.360.cn', port=443): Max retries exceeded with url: /warning/searchbypage?length=6&start=0 (Caused by SSLError(SSLEOFError(8, 'EOF occurred in violation of protocol (_ssl.c:1131)')))

During handling of the above exception, another exception occurred:

Traceback (most recent call last):
  File "/home/runner/work/threat-broadcast-1/threat-broadcast-1/src/crawler/_base_crawler.py", line 62, in cves
    new_cves = self.get_cves()
  File "/home/runner/work/threat-broadcast-1/threat-broadcast-1/src/crawler/cert360.py", line 48, in get_cves
    response = requests.get(
  File "/opt/hostedtoolcache/Python/3.8.12/x64/lib/python3.8/site-packages/requests/api.py", line 75, in get
    return request('get', url, params=params, **kwargs)
  File "/opt/hostedtoolcache/Python/3.8.12/x64/lib/python3.8/site-packages/requests/api.py", line 60, in request
    return session.request(method=method, url=url, **kwargs)
  File "/opt/hostedtoolcache/Python/3.8.12/x64/lib/python3.8/site-packages/requests/sessions.py", line 533, in request
    resp = self.send(prep, **send_kwargs)
  File "/opt/hostedtoolcache/Python/3.8.12/x64/lib/python3.8/site-packages/requests/sessions.py", line 646, in send
    r = adapter.send(request, **kwargs)
  File "/opt/hostedtoolcache/Python/3.8.12/x64/lib/python3.8/site-packages/requests/adapters.py", line 514, in send
    raise SSLError(e, request=request)
requests.exceptions.SSLError: HTTPSConnectionPool(host='cert.360.cn', port=443): Max retries exceeded with url: /warning/searchbypage?length=6&start=0 (Caused by SSLError(SSLEOFError(8, 'EOF occurred in violation of protocol (_ssl.c:1131)')))
2022-04-01 19:52:21 [ERROR] : 获取 [国家信息安全漏洞共享平台（CNVD）] 威胁情报异常
Traceback (most recent call last):
  File "/opt/hostedtoolcache/Python/3.8.12/x64/lib/python3.8/site-packages/urllib3/connectionpool.py", line 426, in _make_request
    six.raise_from(e, None)
  File "<string>", line 3, in raise_from
  File "/opt/hostedtoolcache/Python/3.8.12/x64/lib/python3.8/site-packages/urllib3/connectionpool.py", line 421, in _make_request
    httplib_response = conn.getresponse()
  File "/opt/hostedtoolcache/Python/3.8.12/x64/lib/python3.8/http/client.py", line 1348, in getresponse
    response.begin()
  File "/opt/hostedtoolcache/Python/3.8.12/x64/lib/python3.8/http/client.py", line 316, in begin
    version, status, reason = self._read_status()
  File "/opt/hostedtoolcache/Python/3.8.12/x64/lib/python3.8/http/client.py", line 277, in _read_status
    line = str(self.fp.readline(_MAXLINE + 1), "iso-8859-1")
  File "/opt/hostedtoolcache/Python/3.8.12/x64/lib/python3.8/socket.py", line 669, in readinto
    return self._sock.recv_into(b)
  File "/opt/hostedtoolcache/Python/3.8.12/x64/lib/python3.8/ssl.py", line 1241, in recv_into
    return self.read(nbytes, buffer)
  File "/opt/hostedtoolcache/Python/3.8.12/x64/lib/python3.8/ssl.py", line 1099, in read
    return self._sslobj.read(len, buffer)
socket.timeout: The read operation timed out

During handling of the above exception, another exception occurred:

Traceback (most recent call last):
  File "/opt/hostedtoolcache/Python/3.8.12/x64/lib/python3.8/site-packages/requests/adapters.py", line 439, in send
    resp = conn.urlopen(
  File "/opt/hostedtoolcache/Python/3.8.12/x64/lib/python3.8/site-packages/urllib3/connectionpool.py", line 726, in urlopen
    retries = retries.increment(
  File "/opt/hostedtoolcache/Python/3.8.12/x64/lib/python3.8/site-packages/urllib3/util/retry.py", line 410, in increment
    raise six.reraise(type(error), error, _stacktrace)
  File "/opt/hostedtoolcache/Python/3.8.12/x64/lib/python3.8/site-packages/urllib3/packages/six.py", line 735, in reraise
    raise value
  File "/opt/hostedtoolcache/Python/3.8.12/x64/lib/python3.8/site-packages/urllib3/connectionpool.py", line 670, in urlopen
    httplib_response = self._make_request(
  File "/opt/hostedtoolcache/Python/3.8.12/x64/lib/python3.8/site-packages/urllib3/connectionpool.py", line 428, in _make_request
    self._raise_timeout(err=e, url=url, timeout_value=read_timeout)
  File "/opt/hostedtoolcache/Python/3.8.12/x64/lib/python3.8/site-packages/urllib3/connectionpool.py", line 335, in _raise_timeout
    raise ReadTimeoutError(
urllib3.exceptions.ReadTimeoutError: HTTPSConnectionPool(host='www.cnvd.org.cn', port=443): Read timed out. (read timeout=60)

During handling of the above exception, another exception occurred:

Traceback (most recent call last):
  File "/home/runner/work/threat-broadcast-1/threat-broadcast-1/src/crawler/_base_crawler.py", line 62, in cves
    new_cves = self.get_cves()
  File "/home/runner/work/threat-broadcast-1/threat-broadcast-1/src/crawler/cnvd.py", line 117, in get_cves
    response = self.session.get(
  File "/opt/hostedtoolcache/Python/3.8.12/x64/lib/python3.8/site-packages/requests/sessions.py", line 546, in get
    return self.request('GET', url, **kwargs)
  File "/opt/hostedtoolcache/Python/3.8.12/x64/lib/python3.8/site-packages/requests/sessions.py", line 533, in request
    resp = self.send(prep, **send_kwargs)
  File "/opt/hostedtoolcache/Python/3.8.12/x64/lib/python3.8/site-packages/requests/sessions.py", line 646, in send
    r = adapter.send(request, **kwargs)
  File "/opt/hostedtoolcache/Python/3.8.12/x64/lib/python3.8/site-packages/requests/adapters.py", line 529, in send
    raise ReadTimeout(e, request=request)
requests.exceptions.ReadTimeout: HTTPSConnectionPool(host='www.cnvd.org.cn', port=443): Read timed out. (read timeout=60)
2022-04-01 19:52:21 [ERROR] : Traceback (most recent call last):
  File "/opt/hostedtoolcache/Python/3.8.12/x64/lib/python3.8/site-packages/urllib3/connectionpool.py", line 426, in _make_request
    six.raise_from(e, None)
  File "<string>", line 3, in raise_from
  File "/opt/hostedtoolcache/Python/3.8.12/x64/lib/python3.8/site-packages/urllib3/connectionpool.py", line 421, in _make_request
    httplib_response = conn.getresponse()
  File "/opt/hostedtoolcache/Python/3.8.12/x64/lib/python3.8/http/client.py", line 1348, in getresponse
    response.begin()
  File "/opt/hostedtoolcache/Python/3.8.12/x64/lib/python3.8/http/client.py", line 316, in begin
    version, status, reason = self._read_status()
  File "/opt/hostedtoolcache/Python/3.8.12/x64/lib/python3.8/http/client.py", line 277, in _read_status
    line = str(self.fp.readline(_MAXLINE + 1), "iso-8859-1")
  File "/opt/hostedtoolcache/Python/3.8.12/x64/lib/python3.8/socket.py", line 669, in readinto
    return self._sock.recv_into(b)
  File "/opt/hostedtoolcache/Python/3.8.12/x64/lib/python3.8/ssl.py", line 1241, in recv_into
    return self.read(nbytes, buffer)
  File "/opt/hostedtoolcache/Python/3.8.12/x64/lib/python3.8/ssl.py", line 1099, in read
    return self._sslobj.read(len, buffer)
socket.timeout: The read operation timed out

During handling of the above exception, another exception occurred:

Traceback (most recent call last):
  File "/opt/hostedtoolcache/Python/3.8.12/x64/lib/python3.8/site-packages/requests/adapters.py", line 439, in send
    resp = conn.urlopen(
  File "/opt/hostedtoolcache/Python/3.8.12/x64/lib/python3.8/site-packages/urllib3/connectionpool.py", line 726, in urlopen
    retries = retries.increment(
  File "/opt/hostedtoolcache/Python/3.8.12/x64/lib/python3.8/site-packages/urllib3/util/retry.py", line 410, in increment
    raise six.reraise(type(error), error, _stacktrace)
  File "/opt/hostedtoolcache/Python/3.8.12/x64/lib/python3.8/site-packages/urllib3/packages/six.py", line 735, in reraise
    raise value
  File "/opt/hostedtoolcache/Python/3.8.12/x64/lib/python3.8/site-packages/urllib3/connectionpool.py", line 670, in urlopen
    httplib_response = self._make_request(
  File "/opt/hostedtoolcache/Python/3.8.12/x64/lib/python3.8/site-packages/urllib3/connectionpool.py", line 428, in _make_request
    self._raise_timeout(err=e, url=url, timeout_value=read_timeout)
  File "/opt/hostedtoolcache/Python/3.8.12/x64/lib/python3.8/site-packages/urllib3/connectionpool.py", line 335, in _raise_timeout
    raise ReadTimeoutError(
urllib3.exceptions.ReadTimeoutError: HTTPSConnectionPool(host='www.cnvd.org.cn', port=443): Read timed out. (read timeout=60)

During handling of the above exception, another exception occurred:

Traceback (most recent call last):
  File "/home/runner/work/threat-broadcast-1/threat-broadcast-1/src/crawler/_base_crawler.py", line 62, in cves
    new_cves = self.get_cves()
  File "/home/runner/work/threat-broadcast-1/threat-broadcast-1/src/crawler/cnvd.py", line 117, in get_cves
    response = self.session.get(
  File "/opt/hostedtoolcache/Python/3.8.12/x64/lib/python3.8/site-packages/requests/sessions.py", line 546, in get
    return self.request('GET', url, **kwargs)
  File "/opt/hostedtoolcache/Python/3.8.12/x64/lib/python3.8/site-packages/requests/sessions.py", line 533, in request
    resp = self.send(prep, **send_kwargs)
  File "/opt/hostedtoolcache/Python/3.8.12/x64/lib/python3.8/site-packages/requests/sessions.py", line 646, in send
    r = adapter.send(request, **kwargs)
  File "/opt/hostedtoolcache/Python/3.8.12/x64/lib/python3.8/site-packages/requests/adapters.py", line 529, in send
    raise ReadTimeout(e, request=request)
requests.exceptions.ReadTimeout: HTTPSConnectionPool(host='www.cnvd.org.cn', port=443): Read timed out. (read timeout=60)
Traceback (most recent call last):
  File "/opt/hostedtoolcache/Python/3.8.12/x64/lib/python3.8/site-packages/urllib3/connectionpool.py", line 426, in _make_request
    six.raise_from(e, None)
  File "<string>", line 3, in raise_from
  File "/opt/hostedtoolcache/Python/3.8.12/x64/lib/python3.8/site-packages/urllib3/connectionpool.py", line 421, in _make_request
    httplib_response = conn.getresponse()
  File "/opt/hostedtoolcache/Python/3.8.12/x64/lib/python3.8/http/client.py", line 1348, in getresponse
    response.begin()
  File "/opt/hostedtoolcache/Python/3.8.12/x64/lib/python3.8/http/client.py", line 316, in begin
    version, status, reason = self._read_status()
  File "/opt/hostedtoolcache/Python/3.8.12/x64/lib/python3.8/http/client.py", line 277, in _read_status
    line = str(self.fp.readline(_MAXLINE + 1), "iso-8859-1")
  File "/opt/hostedtoolcache/Python/3.8.12/x64/lib/python3.8/socket.py", line 669, in readinto
    return self._sock.recv_into(b)
  File "/opt/hostedtoolcache/Python/3.8.12/x64/lib/python3.8/ssl.py", line 1241, in recv_into
    return self.read(nbytes, buffer)
  File "/opt/hostedtoolcache/Python/3.8.12/x64/lib/python3.8/ssl.py", line 1099, in read
    return self._sslobj.read(len, buffer)
socket.timeout: The read operation timed out

During handling of the above exception, another exception occurred:

Traceback (most recent call last):
  File "/opt/hostedtoolcache/Python/3.8.12/x64/lib/python3.8/site-packages/requests/adapters.py", line 439, in send
    resp = conn.urlopen(
  File "/opt/hostedtoolcache/Python/3.8.12/x64/lib/python3.8/site-packages/urllib3/connectionpool.py", line 726, in urlopen
    retries = retries.increment(
  File "/opt/hostedtoolcache/Python/3.8.12/x64/lib/python3.8/site-packages/urllib3/util/retry.py", line 410, in increment
    raise six.reraise(type(error), error, _stacktrace)
  File "/opt/hostedtoolcache/Python/3.8.12/x64/lib/python3.8/site-packages/urllib3/packages/six.py", line 735, in reraise
    raise value
  File "/opt/hostedtoolcache/Python/3.8.12/x64/lib/python3.8/site-packages/urllib3/connectionpool.py", line 670, in urlopen
    httplib_response = self._make_request(
  File "/opt/hostedtoolcache/Python/3.8.12/x64/lib/python3.8/site-packages/urllib3/connectionpool.py", line 428, in _make_request
    self._raise_timeout(err=e, url=url, timeout_value=read_timeout)
  File "/opt/hostedtoolcache/Python/3.8.12/x64/lib/python3.8/site-packages/urllib3/connectionpool.py", line 335, in _raise_timeout
    raise ReadTimeoutError(
urllib3.exceptions.ReadTimeoutError: HTTPSConnectionPool(host='www.cnvd.org.cn', port=443): Read timed out. (read timeout=60)

During handling of the above exception, another exception occurred:

Traceback (most recent call last):
  File "/home/runner/work/threat-broadcast-1/threat-broadcast-1/src/crawler/_base_crawler.py", line 62, in cves
    new_cves = self.get_cves()
  File "/home/runner/work/threat-broadcast-1/threat-broadcast-1/src/crawler/cnvd.py", line 117, in get_cves
    response = self.session.get(
  File "/opt/hostedtoolcache/Python/3.8.12/x64/lib/python3.8/site-packages/requests/sessions.py", line 546, in get
    return self.request('GET', url, **kwargs)
  File "/opt/hostedtoolcache/Python/3.8.12/x64/lib/python3.8/site-packages/requests/sessions.py", line 533, in request
    resp = self.send(prep, **send_kwargs)
  File "/opt/hostedtoolcache/Python/3.8.12/x64/lib/python3.8/site-packages/requests/sessions.py", line 646, in send
    r = adapter.send(request, **kwargs)
  File "/opt/hostedtoolcache/Python/3.8.12/x64/lib/python3.8/site-packages/requests/adapters.py", line 529, in send
    raise ReadTimeout(e, request=request)
requests.exceptions.ReadTimeout: HTTPSConnectionPool(host='www.cnvd.org.cn', port=443): Read timed out. (read timeout=60)
