2022-03-24 18:12:52 [ERROR] : 提交变更失败
Traceback (most recent call last):
  File "/root/project/threat-broadcast-1/src/utils/_git.py", line 26, in auto_commit
    repo.git.push()
  File "/usr/local/python3/lib/python3.8/site-packages/git/cmd.py", line 542, in <lambda>
    return lambda *args, **kwargs: self._call_process(name, *args, **kwargs)
  File "/usr/local/python3/lib/python3.8/site-packages/git/cmd.py", line 1005, in _call_process
    return self.execute(call, **exec_kwargs)
  File "/usr/local/python3/lib/python3.8/site-packages/git/cmd.py", line 822, in execute
    raise GitCommandError(command, status, stderr_value, stdout_value)
git.exc.GitCommandError: Cmd('git') failed due to: exit code(128)
  cmdline: git push
  stderr: 'ssh_exchange_identification: read: Connection reset by peer
fatal: Could not read from remote repository.

Please make sure you have the correct access rights
and the repository exists.'
2022-03-24 18:12:52 [ERROR] : Traceback (most recent call last):
  File "/root/project/threat-broadcast-1/src/utils/_git.py", line 26, in auto_commit
    repo.git.push()
  File "/usr/local/python3/lib/python3.8/site-packages/git/cmd.py", line 542, in <lambda>
    return lambda *args, **kwargs: self._call_process(name, *args, **kwargs)
  File "/usr/local/python3/lib/python3.8/site-packages/git/cmd.py", line 1005, in _call_process
    return self.execute(call, **exec_kwargs)
  File "/usr/local/python3/lib/python3.8/site-packages/git/cmd.py", line 822, in execute
    raise GitCommandError(command, status, stderr_value, stdout_value)
git.exc.GitCommandError: Cmd('git') failed due to: exit code(128)
  cmdline: git push
  stderr: 'ssh_exchange_identification: read: Connection reset by peer
fatal: Could not read from remote repository.

Please make sure you have the correct access rights
and the repository exists.'
Traceback (most recent call last):
  File "/root/project/threat-broadcast-1/src/utils/_git.py", line 26, in auto_commit
    repo.git.push()
  File "/usr/local/python3/lib/python3.8/site-packages/git/cmd.py", line 542, in <lambda>
    return lambda *args, **kwargs: self._call_process(name, *args, **kwargs)
  File "/usr/local/python3/lib/python3.8/site-packages/git/cmd.py", line 1005, in _call_process
    return self.execute(call, **exec_kwargs)
  File "/usr/local/python3/lib/python3.8/site-packages/git/cmd.py", line 822, in execute
    raise GitCommandError(command, status, stderr_value, stdout_value)
git.exc.GitCommandError: Cmd('git') failed due to: exit code(128)
  cmdline: git push
  stderr: 'ssh_exchange_identification: read: Connection reset by peer
fatal: Could not read from remote repository.

Please make sure you have the correct access rights
and the repository exists.'
2022-03-24 18:34:52 [ERROR] : 提交变更失败
Traceback (most recent call last):
  File "/root/project/threat-broadcast-1/src/utils/_git.py", line 26, in auto_commit
    repo.git.push()
  File "/usr/local/python3/lib/python3.8/site-packages/git/cmd.py", line 542, in <lambda>
    return lambda *args, **kwargs: self._call_process(name, *args, **kwargs)
  File "/usr/local/python3/lib/python3.8/site-packages/git/cmd.py", line 1005, in _call_process
    return self.execute(call, **exec_kwargs)
  File "/usr/local/python3/lib/python3.8/site-packages/git/cmd.py", line 822, in execute
    raise GitCommandError(command, status, stderr_value, stdout_value)
git.exc.GitCommandError: Cmd('git') failed due to: exit code(128)
  cmdline: git push
  stderr: 'ssh_exchange_identification: read: Connection reset by peer
fatal: Could not read from remote repository.

Please make sure you have the correct access rights
and the repository exists.'
2022-03-24 18:34:52 [ERROR] : Traceback (most recent call last):
  File "/root/project/threat-broadcast-1/src/utils/_git.py", line 26, in auto_commit
    repo.git.push()
  File "/usr/local/python3/lib/python3.8/site-packages/git/cmd.py", line 542, in <lambda>
    return lambda *args, **kwargs: self._call_process(name, *args, **kwargs)
  File "/usr/local/python3/lib/python3.8/site-packages/git/cmd.py", line 1005, in _call_process
    return self.execute(call, **exec_kwargs)
  File "/usr/local/python3/lib/python3.8/site-packages/git/cmd.py", line 822, in execute
    raise GitCommandError(command, status, stderr_value, stdout_value)
git.exc.GitCommandError: Cmd('git') failed due to: exit code(128)
  cmdline: git push
  stderr: 'ssh_exchange_identification: read: Connection reset by peer
fatal: Could not read from remote repository.

Please make sure you have the correct access rights
and the repository exists.'
Traceback (most recent call last):
  File "/root/project/threat-broadcast-1/src/utils/_git.py", line 26, in auto_commit
    repo.git.push()
  File "/usr/local/python3/lib/python3.8/site-packages/git/cmd.py", line 542, in <lambda>
    return lambda *args, **kwargs: self._call_process(name, *args, **kwargs)
  File "/usr/local/python3/lib/python3.8/site-packages/git/cmd.py", line 1005, in _call_process
    return self.execute(call, **exec_kwargs)
  File "/usr/local/python3/lib/python3.8/site-packages/git/cmd.py", line 822, in execute
    raise GitCommandError(command, status, stderr_value, stdout_value)
git.exc.GitCommandError: Cmd('git') failed due to: exit code(128)
  cmdline: git push
  stderr: 'ssh_exchange_identification: read: Connection reset by peer
fatal: Could not read from remote repository.

Please make sure you have the correct access rights
and the repository exists.'
