2022-03-18 16:40:25 [ERROR] : [邮件] 推送威胁情报失败
Traceback (most recent call last):
  File "/root/project/threat-broadcast-1/src/notice/mail.py", line 46, in to_mail
    smtpObj.login(sender, password)
  File "/usr/local/python3/lib/python3.8/smtplib.py", line 723, in login
    (code, resp) = self.auth(
  File "/usr/local/python3/lib/python3.8/smtplib.py", line 642, in auth
    authobject(challenge).encode('ascii'), eol='')
AttributeError: 'NoneType' object has no attribute 'encode'
2022-03-18 16:40:25 [ERROR] : Traceback (most recent call last):
  File "/root/project/threat-broadcast-1/src/notice/mail.py", line 46, in to_mail
    smtpObj.login(sender, password)
  File "/usr/local/python3/lib/python3.8/smtplib.py", line 723, in login
    (code, resp) = self.auth(
  File "/usr/local/python3/lib/python3.8/smtplib.py", line 642, in auth
    authobject(challenge).encode('ascii'), eol='')
AttributeError: 'NoneType' object has no attribute 'encode'
Traceback (most recent call last):
  File "/root/project/threat-broadcast-1/src/notice/mail.py", line 46, in to_mail
    smtpObj.login(sender, password)
  File "/usr/local/python3/lib/python3.8/smtplib.py", line 723, in login
    (code, resp) = self.auth(
  File "/usr/local/python3/lib/python3.8/smtplib.py", line 642, in auth
    authobject(challenge).encode('ascii'), eol='')
AttributeError: 'NoneType' object has no attribute 'encode'
2022-03-18 16:40:26 [ERROR] : 提交变更失败
Traceback (most recent call last):
  File "/root/project/threat-broadcast-1/src/utils/_git.py", line 26, in auto_commit
    repo.git.push()
  File "/usr/local/python3/lib/python3.8/site-packages/git/cmd.py", line 542, in <lambda>
    return lambda *args, **kwargs: self._call_process(name, *args, **kwargs)
  File "/usr/local/python3/lib/python3.8/site-packages/git/cmd.py", line 1005, in _call_process
    return self.execute(call, **exec_kwargs)
  File "/usr/local/python3/lib/python3.8/site-packages/git/cmd.py", line 822, in execute
    raise GitCommandError(command, status, stderr_value, stdout_value)
git.exc.GitCommandError: Cmd('git') failed due to: exit code(128)
  cmdline: git push
  stderr: 'ssh_exchange_identification: read: Connection reset by peer
fatal: Could not read from remote repository.

Please make sure you have the correct access rights
and the repository exists.'
2022-03-18 16:40:26 [ERROR] : Traceback (most recent call last):
  File "/root/project/threat-broadcast-1/src/utils/_git.py", line 26, in auto_commit
    repo.git.push()
  File "/usr/local/python3/lib/python3.8/site-packages/git/cmd.py", line 542, in <lambda>
    return lambda *args, **kwargs: self._call_process(name, *args, **kwargs)
  File "/usr/local/python3/lib/python3.8/site-packages/git/cmd.py", line 1005, in _call_process
    return self.execute(call, **exec_kwargs)
  File "/usr/local/python3/lib/python3.8/site-packages/git/cmd.py", line 822, in execute
    raise GitCommandError(command, status, stderr_value, stdout_value)
git.exc.GitCommandError: Cmd('git') failed due to: exit code(128)
  cmdline: git push
  stderr: 'ssh_exchange_identification: read: Connection reset by peer
fatal: Could not read from remote repository.

Please make sure you have the correct access rights
and the repository exists.'
Traceback (most recent call last):
  File "/root/project/threat-broadcast-1/src/utils/_git.py", line 26, in auto_commit
    repo.git.push()
  File "/usr/local/python3/lib/python3.8/site-packages/git/cmd.py", line 542, in <lambda>
    return lambda *args, **kwargs: self._call_process(name, *args, **kwargs)
  File "/usr/local/python3/lib/python3.8/site-packages/git/cmd.py", line 1005, in _call_process
    return self.execute(call, **exec_kwargs)
  File "/usr/local/python3/lib/python3.8/site-packages/git/cmd.py", line 822, in execute
    raise GitCommandError(command, status, stderr_value, stdout_value)
git.exc.GitCommandError: Cmd('git') failed due to: exit code(128)
  cmdline: git push
  stderr: 'ssh_exchange_identification: read: Connection reset by peer
fatal: Could not read from remote repository.

Please make sure you have the correct access rights
and the repository exists.'
2022-03-18 16:42:27 [ERROR] : [邮件] 推送威胁情报失败
Traceback (most recent call last):
  File "/root/project/threat-broadcast-1/src/notice/mail.py", line 46, in to_mail
    smtpObj.login(sender, password)
  File "/usr/local/python3/lib/python3.8/smtplib.py", line 723, in login
    (code, resp) = self.auth(
  File "/usr/local/python3/lib/python3.8/smtplib.py", line 642, in auth
    authobject(challenge).encode('ascii'), eol='')
AttributeError: 'NoneType' object has no attribute 'encode'
2022-03-18 16:42:27 [ERROR] : Traceback (most recent call last):
  File "/root/project/threat-broadcast-1/src/notice/mail.py", line 46, in to_mail
    smtpObj.login(sender, password)
  File "/usr/local/python3/lib/python3.8/smtplib.py", line 723, in login
    (code, resp) = self.auth(
  File "/usr/local/python3/lib/python3.8/smtplib.py", line 642, in auth
    authobject(challenge).encode('ascii'), eol='')
AttributeError: 'NoneType' object has no attribute 'encode'
Traceback (most recent call last):
  File "/root/project/threat-broadcast-1/src/notice/mail.py", line 46, in to_mail
    smtpObj.login(sender, password)
  File "/usr/local/python3/lib/python3.8/smtplib.py", line 723, in login
    (code, resp) = self.auth(
  File "/usr/local/python3/lib/python3.8/smtplib.py", line 642, in auth
    authobject(challenge).encode('ascii'), eol='')
AttributeError: 'NoneType' object has no attribute 'encode'
2022-03-18 16:45:51 [ERROR] : [邮件] 推送威胁情报失败
Traceback (most recent call last):
  File "/root/project/threat-broadcast-1/src/notice/mail.py", line 46, in to_mail
    smtpObj.login(sender, password)
  File "/usr/local/python3/lib/python3.8/smtplib.py", line 723, in login
    (code, resp) = self.auth(
  File "/usr/local/python3/lib/python3.8/smtplib.py", line 642, in auth
    authobject(challenge).encode('ascii'), eol='')
AttributeError: 'NoneType' object has no attribute 'encode'
2022-03-18 16:45:51 [ERROR] : Traceback (most recent call last):
  File "/root/project/threat-broadcast-1/src/notice/mail.py", line 46, in to_mail
    smtpObj.login(sender, password)
  File "/usr/local/python3/lib/python3.8/smtplib.py", line 723, in login
    (code, resp) = self.auth(
  File "/usr/local/python3/lib/python3.8/smtplib.py", line 642, in auth
    authobject(challenge).encode('ascii'), eol='')
AttributeError: 'NoneType' object has no attribute 'encode'
Traceback (most recent call last):
  File "/root/project/threat-broadcast-1/src/notice/mail.py", line 46, in to_mail
    smtpObj.login(sender, password)
  File "/usr/local/python3/lib/python3.8/smtplib.py", line 723, in login
    (code, resp) = self.auth(
  File "/usr/local/python3/lib/python3.8/smtplib.py", line 642, in auth
    authobject(challenge).encode('ascii'), eol='')
AttributeError: 'NoneType' object has no attribute 'encode'
2022-03-18 16:45:51 [ERROR] : 提交变更失败
Traceback (most recent call last):
  File "/root/project/threat-broadcast-1/src/utils/_git.py", line 26, in auto_commit
    repo.git.push()
  File "/usr/local/python3/lib/python3.8/site-packages/git/cmd.py", line 542, in <lambda>
    return lambda *args, **kwargs: self._call_process(name, *args, **kwargs)
  File "/usr/local/python3/lib/python3.8/site-packages/git/cmd.py", line 1005, in _call_process
    return self.execute(call, **exec_kwargs)
  File "/usr/local/python3/lib/python3.8/site-packages/git/cmd.py", line 822, in execute
    raise GitCommandError(command, status, stderr_value, stdout_value)
git.exc.GitCommandError: Cmd('git') failed due to: exit code(128)
  cmdline: git push
  stderr: 'ssh_exchange_identification: read: Connection reset by peer
fatal: Could not read from remote repository.

Please make sure you have the correct access rights
and the repository exists.'
2022-03-18 16:45:51 [ERROR] : Traceback (most recent call last):
  File "/root/project/threat-broadcast-1/src/utils/_git.py", line 26, in auto_commit
    repo.git.push()
  File "/usr/local/python3/lib/python3.8/site-packages/git/cmd.py", line 542, in <lambda>
    return lambda *args, **kwargs: self._call_process(name, *args, **kwargs)
  File "/usr/local/python3/lib/python3.8/site-packages/git/cmd.py", line 1005, in _call_process
    return self.execute(call, **exec_kwargs)
  File "/usr/local/python3/lib/python3.8/site-packages/git/cmd.py", line 822, in execute
    raise GitCommandError(command, status, stderr_value, stdout_value)
git.exc.GitCommandError: Cmd('git') failed due to: exit code(128)
  cmdline: git push
  stderr: 'ssh_exchange_identification: read: Connection reset by peer
fatal: Could not read from remote repository.

Please make sure you have the correct access rights
and the repository exists.'
Traceback (most recent call last):
  File "/root/project/threat-broadcast-1/src/utils/_git.py", line 26, in auto_commit
    repo.git.push()
  File "/usr/local/python3/lib/python3.8/site-packages/git/cmd.py", line 542, in <lambda>
    return lambda *args, **kwargs: self._call_process(name, *args, **kwargs)
  File "/usr/local/python3/lib/python3.8/site-packages/git/cmd.py", line 1005, in _call_process
    return self.execute(call, **exec_kwargs)
  File "/usr/local/python3/lib/python3.8/site-packages/git/cmd.py", line 822, in execute
    raise GitCommandError(command, status, stderr_value, stdout_value)
git.exc.GitCommandError: Cmd('git') failed due to: exit code(128)
  cmdline: git push
  stderr: 'ssh_exchange_identification: read: Connection reset by peer
fatal: Could not read from remote repository.

Please make sure you have the correct access rights
and the repository exists.'
2022-03-18 16:50:09 [ERROR] : [邮件] 推送威胁情报失败
Traceback (most recent call last):
  File "/root/project/threat-broadcast-1/src/notice/mail.py", line 47, in to_mail
    smtpObj.login(sender, password)
  File "/usr/local/python3/lib/python3.8/smtplib.py", line 723, in login
    (code, resp) = self.auth(
  File "/usr/local/python3/lib/python3.8/smtplib.py", line 642, in auth
    authobject(challenge).encode('ascii'), eol='')
AttributeError: 'NoneType' object has no attribute 'encode'
2022-03-18 16:50:09 [ERROR] : Traceback (most recent call last):
  File "/root/project/threat-broadcast-1/src/notice/mail.py", line 47, in to_mail
    smtpObj.login(sender, password)
  File "/usr/local/python3/lib/python3.8/smtplib.py", line 723, in login
    (code, resp) = self.auth(
  File "/usr/local/python3/lib/python3.8/smtplib.py", line 642, in auth
    authobject(challenge).encode('ascii'), eol='')
AttributeError: 'NoneType' object has no attribute 'encode'
Traceback (most recent call last):
  File "/root/project/threat-broadcast-1/src/notice/mail.py", line 47, in to_mail
    smtpObj.login(sender, password)
  File "/usr/local/python3/lib/python3.8/smtplib.py", line 723, in login
    (code, resp) = self.auth(
  File "/usr/local/python3/lib/python3.8/smtplib.py", line 642, in auth
    authobject(challenge).encode('ascii'), eol='')
AttributeError: 'NoneType' object has no attribute 'encode'
2022-03-18 22:41:11 [ERROR] : [邮件] 推送威胁情报失败
Traceback (most recent call last):
  File "/root/project/threat-broadcast-1/src/notice/mail.py", line 46, in to_mail
    smtpObj.login(sender, password)
  File "/usr/local/python3/lib/python3.8/smtplib.py", line 734, in login
    raise last_exception
  File "/usr/local/python3/lib/python3.8/smtplib.py", line 723, in login
    (code, resp) = self.auth(
  File "/usr/local/python3/lib/python3.8/smtplib.py", line 646, in auth
    raise SMTPAuthenticationError(code, resp)
smtplib.SMTPAuthenticationError: (535, b'Login Fail. Please enter your authorization code to login. More information in http://service.mail.qq.com/cgi-bin/help?subtype=1&&id=28&&no=1001256')
2022-03-18 22:41:11 [ERROR] : Traceback (most recent call last):
  File "/root/project/threat-broadcast-1/src/notice/mail.py", line 46, in to_mail
    smtpObj.login(sender, password)
  File "/usr/local/python3/lib/python3.8/smtplib.py", line 734, in login
    raise last_exception
  File "/usr/local/python3/lib/python3.8/smtplib.py", line 723, in login
    (code, resp) = self.auth(
  File "/usr/local/python3/lib/python3.8/smtplib.py", line 646, in auth
    raise SMTPAuthenticationError(code, resp)
smtplib.SMTPAuthenticationError: (535, b'Login Fail. Please enter your authorization code to login. More information in http://service.mail.qq.com/cgi-bin/help?subtype=1&&id=28&&no=1001256')
Traceback (most recent call last):
  File "/root/project/threat-broadcast-1/src/notice/mail.py", line 46, in to_mail
    smtpObj.login(sender, password)
  File "/usr/local/python3/lib/python3.8/smtplib.py", line 734, in login
    raise last_exception
  File "/usr/local/python3/lib/python3.8/smtplib.py", line 723, in login
    (code, resp) = self.auth(
  File "/usr/local/python3/lib/python3.8/smtplib.py", line 646, in auth
    raise SMTPAuthenticationError(code, resp)
smtplib.SMTPAuthenticationError: (535, b'Login Fail. Please enter your authorization code to login. More information in http://service.mail.qq.com/cgi-bin/help?subtype=1&&id=28&&no=1001256')
2022-03-18 22:41:14 [ERROR] : 提交变更失败
Traceback (most recent call last):
  File "/root/project/threat-broadcast-1/src/utils/_git.py", line 26, in auto_commit
    repo.git.push()
  File "/usr/local/python3/lib/python3.8/site-packages/git/cmd.py", line 542, in <lambda>
    return lambda *args, **kwargs: self._call_process(name, *args, **kwargs)
  File "/usr/local/python3/lib/python3.8/site-packages/git/cmd.py", line 1005, in _call_process
    return self.execute(call, **exec_kwargs)
  File "/usr/local/python3/lib/python3.8/site-packages/git/cmd.py", line 822, in execute
    raise GitCommandError(command, status, stderr_value, stdout_value)
git.exc.GitCommandError: Cmd('git') failed due to: exit code(1)
  cmdline: git push
  stderr: 'To git@github.com:hkmayfly/threat-broadcast-1.git
 ! [rejected]        master -> master (fetch first)
error: failed to push some refs to 'git@github.com:hkmayfly/threat-broadcast-1.git'
hint: Updates were rejected because the remote contains work that you do
hint: not have locally. This is usually caused by another repository pushing
hint: to the same ref. You may want to first merge the remote changes (e.g.,
hint: 'git pull') before pushing again.
hint: See the 'Note about fast-forwards' in 'git push --help' for details.'
2022-03-18 22:41:14 [ERROR] : Traceback (most recent call last):
  File "/root/project/threat-broadcast-1/src/utils/_git.py", line 26, in auto_commit
    repo.git.push()
  File "/usr/local/python3/lib/python3.8/site-packages/git/cmd.py", line 542, in <lambda>
    return lambda *args, **kwargs: self._call_process(name, *args, **kwargs)
  File "/usr/local/python3/lib/python3.8/site-packages/git/cmd.py", line 1005, in _call_process
    return self.execute(call, **exec_kwargs)
  File "/usr/local/python3/lib/python3.8/site-packages/git/cmd.py", line 822, in execute
    raise GitCommandError(command, status, stderr_value, stdout_value)
git.exc.GitCommandError: Cmd('git') failed due to: exit code(1)
  cmdline: git push
  stderr: 'To git@github.com:hkmayfly/threat-broadcast-1.git
 ! [rejected]        master -> master (fetch first)
error: failed to push some refs to 'git@github.com:hkmayfly/threat-broadcast-1.git'
hint: Updates were rejected because the remote contains work that you do
hint: not have locally. This is usually caused by another repository pushing
hint: to the same ref. You may want to first merge the remote changes (e.g.,
hint: 'git pull') before pushing again.
hint: See the 'Note about fast-forwards' in 'git push --help' for details.'
Traceback (most recent call last):
  File "/root/project/threat-broadcast-1/src/utils/_git.py", line 26, in auto_commit
    repo.git.push()
  File "/usr/local/python3/lib/python3.8/site-packages/git/cmd.py", line 542, in <lambda>
    return lambda *args, **kwargs: self._call_process(name, *args, **kwargs)
  File "/usr/local/python3/lib/python3.8/site-packages/git/cmd.py", line 1005, in _call_process
    return self.execute(call, **exec_kwargs)
  File "/usr/local/python3/lib/python3.8/site-packages/git/cmd.py", line 822, in execute
    raise GitCommandError(command, status, stderr_value, stdout_value)
git.exc.GitCommandError: Cmd('git') failed due to: exit code(1)
  cmdline: git push
  stderr: 'To git@github.com:hkmayfly/threat-broadcast-1.git
 ! [rejected]        master -> master (fetch first)
error: failed to push some refs to 'git@github.com:hkmayfly/threat-broadcast-1.git'
hint: Updates were rejected because the remote contains work that you do
hint: not have locally. This is usually caused by another repository pushing
hint: to the same ref. You may want to first merge the remote changes (e.g.,
hint: 'git pull') before pushing again.
hint: See the 'Note about fast-forwards' in 'git push --help' for details.'
2022-03-18 22:52:28 [ERROR] : [邮件] 推送威胁情报失败
Traceback (most recent call last):
  File "/root/project/threat-broadcast-1/src/notice/mail.py", line 47, in to_mail
    smtpObj.login(sender, password)
  File "/usr/local/python3/lib/python3.8/smtplib.py", line 734, in login
    raise last_exception
  File "/usr/local/python3/lib/python3.8/smtplib.py", line 723, in login
    (code, resp) = self.auth(
  File "/usr/local/python3/lib/python3.8/smtplib.py", line 646, in auth
    raise SMTPAuthenticationError(code, resp)
smtplib.SMTPAuthenticationError: (535, b'Login Fail. Please enter your authorization code to login. More information in http://service.mail.qq.com/cgi-bin/help?subtype=1&&id=28&&no=1001256')
2022-03-18 22:52:28 [ERROR] : Traceback (most recent call last):
  File "/root/project/threat-broadcast-1/src/notice/mail.py", line 47, in to_mail
    smtpObj.login(sender, password)
  File "/usr/local/python3/lib/python3.8/smtplib.py", line 734, in login
    raise last_exception
  File "/usr/local/python3/lib/python3.8/smtplib.py", line 723, in login
    (code, resp) = self.auth(
  File "/usr/local/python3/lib/python3.8/smtplib.py", line 646, in auth
    raise SMTPAuthenticationError(code, resp)
smtplib.SMTPAuthenticationError: (535, b'Login Fail. Please enter your authorization code to login. More information in http://service.mail.qq.com/cgi-bin/help?subtype=1&&id=28&&no=1001256')
Traceback (most recent call last):
  File "/root/project/threat-broadcast-1/src/notice/mail.py", line 47, in to_mail
    smtpObj.login(sender, password)
  File "/usr/local/python3/lib/python3.8/smtplib.py", line 734, in login
    raise last_exception
  File "/usr/local/python3/lib/python3.8/smtplib.py", line 723, in login
    (code, resp) = self.auth(
  File "/usr/local/python3/lib/python3.8/smtplib.py", line 646, in auth
    raise SMTPAuthenticationError(code, resp)
smtplib.SMTPAuthenticationError: (535, b'Login Fail. Please enter your authorization code to login. More information in http://service.mail.qq.com/cgi-bin/help?subtype=1&&id=28&&no=1001256')
