2022-04-01 10:20:11 [ERROR] : 提交变更失败
Traceback (most recent call last):
  File "/root/project/threat-broadcast-1/src/utils/_git.py", line 26, in auto_commit
    repo.git.push()
  File "/usr/local/python3/lib/python3.8/site-packages/git/cmd.py", line 542, in <lambda>
    return lambda *args, **kwargs: self._call_process(name, *args, **kwargs)
  File "/usr/local/python3/lib/python3.8/site-packages/git/cmd.py", line 1005, in _call_process
    return self.execute(call, **exec_kwargs)
  File "/usr/local/python3/lib/python3.8/site-packages/git/cmd.py", line 822, in execute
    raise GitCommandError(command, status, stderr_value, stdout_value)
git.exc.GitCommandError: Cmd('git') failed due to: exit code(1)
  cmdline: git push
  stderr: 'To git@github.com:hkmayfly/threat-broadcast-1.git
 ! [rejected]        master -> master (fetch first)
error: failed to push some refs to 'git@github.com:hkmayfly/threat-broadcast-1.git'
hint: Updates were rejected because the remote contains work that you do
hint: not have locally. This is usually caused by another repository pushing
hint: to the same ref. You may want to first merge the remote changes (e.g.,
hint: 'git pull') before pushing again.
hint: See the 'Note about fast-forwards' in 'git push --help' for details.'
2022-04-01 10:20:11 [ERROR] : Traceback (most recent call last):
  File "/root/project/threat-broadcast-1/src/utils/_git.py", line 26, in auto_commit
    repo.git.push()
  File "/usr/local/python3/lib/python3.8/site-packages/git/cmd.py", line 542, in <lambda>
    return lambda *args, **kwargs: self._call_process(name, *args, **kwargs)
  File "/usr/local/python3/lib/python3.8/site-packages/git/cmd.py", line 1005, in _call_process
    return self.execute(call, **exec_kwargs)
  File "/usr/local/python3/lib/python3.8/site-packages/git/cmd.py", line 822, in execute
    raise GitCommandError(command, status, stderr_value, stdout_value)
git.exc.GitCommandError: Cmd('git') failed due to: exit code(1)
  cmdline: git push
  stderr: 'To git@github.com:hkmayfly/threat-broadcast-1.git
 ! [rejected]        master -> master (fetch first)
error: failed to push some refs to 'git@github.com:hkmayfly/threat-broadcast-1.git'
hint: Updates were rejected because the remote contains work that you do
hint: not have locally. This is usually caused by another repository pushing
hint: to the same ref. You may want to first merge the remote changes (e.g.,
hint: 'git pull') before pushing again.
hint: See the 'Note about fast-forwards' in 'git push --help' for details.'
Traceback (most recent call last):
  File "/root/project/threat-broadcast-1/src/utils/_git.py", line 26, in auto_commit
    repo.git.push()
  File "/usr/local/python3/lib/python3.8/site-packages/git/cmd.py", line 542, in <lambda>
    return lambda *args, **kwargs: self._call_process(name, *args, **kwargs)
  File "/usr/local/python3/lib/python3.8/site-packages/git/cmd.py", line 1005, in _call_process
    return self.execute(call, **exec_kwargs)
  File "/usr/local/python3/lib/python3.8/site-packages/git/cmd.py", line 822, in execute
    raise GitCommandError(command, status, stderr_value, stdout_value)
git.exc.GitCommandError: Cmd('git') failed due to: exit code(1)
  cmdline: git push
  stderr: 'To git@github.com:hkmayfly/threat-broadcast-1.git
 ! [rejected]        master -> master (fetch first)
error: failed to push some refs to 'git@github.com:hkmayfly/threat-broadcast-1.git'
hint: Updates were rejected because the remote contains work that you do
hint: not have locally. This is usually caused by another repository pushing
hint: to the same ref. You may want to first merge the remote changes (e.g.,
hint: 'git pull') before pushing again.
hint: See the 'Note about fast-forwards' in 'git push --help' for details.'
2022-04-01 10:23:06 [ERROR] : 提交变更失败
Traceback (most recent call last):
  File "/root/project/threat-broadcast-1/src/utils/_git.py", line 26, in auto_commit
    repo.git.push()
  File "/usr/local/python3/lib/python3.8/site-packages/git/cmd.py", line 542, in <lambda>
    return lambda *args, **kwargs: self._call_process(name, *args, **kwargs)
  File "/usr/local/python3/lib/python3.8/site-packages/git/cmd.py", line 1005, in _call_process
    return self.execute(call, **exec_kwargs)
  File "/usr/local/python3/lib/python3.8/site-packages/git/cmd.py", line 822, in execute
    raise GitCommandError(command, status, stderr_value, stdout_value)
git.exc.GitCommandError: Cmd('git') failed due to: exit code(1)
  cmdline: git push
  stderr: 'To git@github.com:hkmayfly/threat-broadcast-1.git
 ! [rejected]        master -> master (fetch first)
error: failed to push some refs to 'git@github.com:hkmayfly/threat-broadcast-1.git'
hint: Updates were rejected because the remote contains work that you do
hint: not have locally. This is usually caused by another repository pushing
hint: to the same ref. You may want to first merge the remote changes (e.g.,
hint: 'git pull') before pushing again.
hint: See the 'Note about fast-forwards' in 'git push --help' for details.'
2022-04-01 10:23:06 [ERROR] : Traceback (most recent call last):
  File "/root/project/threat-broadcast-1/src/utils/_git.py", line 26, in auto_commit
    repo.git.push()
  File "/usr/local/python3/lib/python3.8/site-packages/git/cmd.py", line 542, in <lambda>
    return lambda *args, **kwargs: self._call_process(name, *args, **kwargs)
  File "/usr/local/python3/lib/python3.8/site-packages/git/cmd.py", line 1005, in _call_process
    return self.execute(call, **exec_kwargs)
  File "/usr/local/python3/lib/python3.8/site-packages/git/cmd.py", line 822, in execute
    raise GitCommandError(command, status, stderr_value, stdout_value)
git.exc.GitCommandError: Cmd('git') failed due to: exit code(1)
  cmdline: git push
  stderr: 'To git@github.com:hkmayfly/threat-broadcast-1.git
 ! [rejected]        master -> master (fetch first)
error: failed to push some refs to 'git@github.com:hkmayfly/threat-broadcast-1.git'
hint: Updates were rejected because the remote contains work that you do
hint: not have locally. This is usually caused by another repository pushing
hint: to the same ref. You may want to first merge the remote changes (e.g.,
hint: 'git pull') before pushing again.
hint: See the 'Note about fast-forwards' in 'git push --help' for details.'
Traceback (most recent call last):
  File "/root/project/threat-broadcast-1/src/utils/_git.py", line 26, in auto_commit
    repo.git.push()
  File "/usr/local/python3/lib/python3.8/site-packages/git/cmd.py", line 542, in <lambda>
    return lambda *args, **kwargs: self._call_process(name, *args, **kwargs)
  File "/usr/local/python3/lib/python3.8/site-packages/git/cmd.py", line 1005, in _call_process
    return self.execute(call, **exec_kwargs)
  File "/usr/local/python3/lib/python3.8/site-packages/git/cmd.py", line 822, in execute
    raise GitCommandError(command, status, stderr_value, stdout_value)
git.exc.GitCommandError: Cmd('git') failed due to: exit code(1)
  cmdline: git push
  stderr: 'To git@github.com:hkmayfly/threat-broadcast-1.git
 ! [rejected]        master -> master (fetch first)
error: failed to push some refs to 'git@github.com:hkmayfly/threat-broadcast-1.git'
hint: Updates were rejected because the remote contains work that you do
hint: not have locally. This is usually caused by another repository pushing
hint: to the same ref. You may want to first merge the remote changes (e.g.,
hint: 'git pull') before pushing again.
hint: See the 'Note about fast-forwards' in 'git push --help' for details.'
2022-04-01 11:58:56 [ERROR] : 提交变更失败
Traceback (most recent call last):
  File "/root/project/threat-broadcast-1/src/utils/_git.py", line 26, in auto_commit
    repo.git.push()
  File "/usr/local/python3/lib/python3.8/site-packages/git/cmd.py", line 542, in <lambda>
    return lambda *args, **kwargs: self._call_process(name, *args, **kwargs)
  File "/usr/local/python3/lib/python3.8/site-packages/git/cmd.py", line 1005, in _call_process
    return self.execute(call, **exec_kwargs)
  File "/usr/local/python3/lib/python3.8/site-packages/git/cmd.py", line 822, in execute
    raise GitCommandError(command, status, stderr_value, stdout_value)
git.exc.GitCommandError: Cmd('git') failed due to: exit code(1)
  cmdline: git push
  stderr: 'To git@github.com:hkmayfly/threat-broadcast-1.git
 ! [rejected]        master -> master (fetch first)
error: failed to push some refs to 'git@github.com:hkmayfly/threat-broadcast-1.git'
hint: Updates were rejected because the remote contains work that you do
hint: not have locally. This is usually caused by another repository pushing
hint: to the same ref. You may want to first merge the remote changes (e.g.,
hint: 'git pull') before pushing again.
hint: See the 'Note about fast-forwards' in 'git push --help' for details.'
2022-04-01 11:58:56 [ERROR] : Traceback (most recent call last):
  File "/root/project/threat-broadcast-1/src/utils/_git.py", line 26, in auto_commit
    repo.git.push()
  File "/usr/local/python3/lib/python3.8/site-packages/git/cmd.py", line 542, in <lambda>
    return lambda *args, **kwargs: self._call_process(name, *args, **kwargs)
  File "/usr/local/python3/lib/python3.8/site-packages/git/cmd.py", line 1005, in _call_process
    return self.execute(call, **exec_kwargs)
  File "/usr/local/python3/lib/python3.8/site-packages/git/cmd.py", line 822, in execute
    raise GitCommandError(command, status, stderr_value, stdout_value)
git.exc.GitCommandError: Cmd('git') failed due to: exit code(1)
  cmdline: git push
  stderr: 'To git@github.com:hkmayfly/threat-broadcast-1.git
 ! [rejected]        master -> master (fetch first)
error: failed to push some refs to 'git@github.com:hkmayfly/threat-broadcast-1.git'
hint: Updates were rejected because the remote contains work that you do
hint: not have locally. This is usually caused by another repository pushing
hint: to the same ref. You may want to first merge the remote changes (e.g.,
hint: 'git pull') before pushing again.
hint: See the 'Note about fast-forwards' in 'git push --help' for details.'
Traceback (most recent call last):
  File "/root/project/threat-broadcast-1/src/utils/_git.py", line 26, in auto_commit
    repo.git.push()
  File "/usr/local/python3/lib/python3.8/site-packages/git/cmd.py", line 542, in <lambda>
    return lambda *args, **kwargs: self._call_process(name, *args, **kwargs)
  File "/usr/local/python3/lib/python3.8/site-packages/git/cmd.py", line 1005, in _call_process
    return self.execute(call, **exec_kwargs)
  File "/usr/local/python3/lib/python3.8/site-packages/git/cmd.py", line 822, in execute
    raise GitCommandError(command, status, stderr_value, stdout_value)
git.exc.GitCommandError: Cmd('git') failed due to: exit code(1)
  cmdline: git push
  stderr: 'To git@github.com:hkmayfly/threat-broadcast-1.git
 ! [rejected]        master -> master (fetch first)
error: failed to push some refs to 'git@github.com:hkmayfly/threat-broadcast-1.git'
hint: Updates were rejected because the remote contains work that you do
hint: not have locally. This is usually caused by another repository pushing
hint: to the same ref. You may want to first merge the remote changes (e.g.,
hint: 'git pull') before pushing again.
hint: See the 'Note about fast-forwards' in 'git push --help' for details.'
