2022-03-18 16:40:25 [ERROR] : [邮件] 推送威胁情报失败
Traceback (most recent call last):
  File "/root/project/threat-broadcast-1/src/notice/mail.py", line 46, in to_mail
    smtpObj.login(sender, password)
  File "/usr/local/python3/lib/python3.8/smtplib.py", line 723, in login
    (code, resp) = self.auth(
  File "/usr/local/python3/lib/python3.8/smtplib.py", line 642, in auth
    authobject(challenge).encode('ascii'), eol='')
AttributeError: 'NoneType' object has no attribute 'encode'
2022-03-18 16:40:25 [ERROR] : Traceback (most recent call last):
  File "/root/project/threat-broadcast-1/src/notice/mail.py", line 46, in to_mail
    smtpObj.login(sender, password)
  File "/usr/local/python3/lib/python3.8/smtplib.py", line 723, in login
    (code, resp) = self.auth(
  File "/usr/local/python3/lib/python3.8/smtplib.py", line 642, in auth
    authobject(challenge).encode('ascii'), eol='')
AttributeError: 'NoneType' object has no attribute 'encode'
Traceback (most recent call last):
  File "/root/project/threat-broadcast-1/src/notice/mail.py", line 46, in to_mail
    smtpObj.login(sender, password)
  File "/usr/local/python3/lib/python3.8/smtplib.py", line 723, in login
    (code, resp) = self.auth(
  File "/usr/local/python3/lib/python3.8/smtplib.py", line 642, in auth
    authobject(challenge).encode('ascii'), eol='')
AttributeError: 'NoneType' object has no attribute 'encode'
