2022-04-27 11:11:52 [ERROR] : 获取 [数字观星POC++] 威胁情报异常
Traceback (most recent call last):
  File "/usr/local/python3/lib/python3.8/site-packages/urllib3/connectionpool.py", line 381, in _make_request
    self._validate_conn(conn)
  File "/usr/local/python3/lib/python3.8/site-packages/urllib3/connectionpool.py", line 978, in _validate_conn
    conn.connect()
  File "/usr/local/python3/lib/python3.8/site-packages/urllib3/connection.py", line 362, in connect
    self.sock = ssl_wrap_socket(
  File "/usr/local/python3/lib/python3.8/site-packages/urllib3/util/ssl_.py", line 386, in ssl_wrap_socket
    return context.wrap_socket(sock, server_hostname=server_hostname)
  File "/usr/local/python3/lib/python3.8/ssl.py", line 500, in wrap_socket
    return self.sslsocket_class._create(
  File "/usr/local/python3/lib/python3.8/ssl.py", line 1040, in _create
    self.do_handshake()
  File "/usr/local/python3/lib/python3.8/ssl.py", line 1309, in do_handshake
    self._sslobj.do_handshake()
socket.timeout: _ssl.c:1091: The handshake operation timed out

During handling of the above exception, another exception occurred:

Traceback (most recent call last):
  File "/usr/local/python3/lib/python3.8/site-packages/requests/adapters.py", line 439, in send
    resp = conn.urlopen(
  File "/usr/local/python3/lib/python3.8/site-packages/urllib3/connectionpool.py", line 726, in urlopen
    retries = retries.increment(
  File "/usr/local/python3/lib/python3.8/site-packages/urllib3/util/retry.py", line 410, in increment
    raise six.reraise(type(error), error, _stacktrace)
  File "/usr/local/python3/lib/python3.8/site-packages/urllib3/packages/six.py", line 735, in reraise
    raise value
  File "/usr/local/python3/lib/python3.8/site-packages/urllib3/connectionpool.py", line 670, in urlopen
    httplib_response = self._make_request(
  File "/usr/local/python3/lib/python3.8/site-packages/urllib3/connectionpool.py", line 384, in _make_request
    self._raise_timeout(err=e, url=url, timeout_value=conn.timeout)
  File "/usr/local/python3/lib/python3.8/site-packages/urllib3/connectionpool.py", line 335, in _raise_timeout
    raise ReadTimeoutError(
urllib3.exceptions.ReadTimeoutError: HTTPSConnectionPool(host='poc.shuziguanxing.com', port=443): Read timed out. (read timeout=60)

During handling of the above exception, another exception occurred:

Traceback (most recent call last):
  File "/root/project/threat-broadcast-1/src/crawler/_base_crawler.py", line 62, in cves
    new_cves = self.get_cves()
  File "/root/project/threat-broadcast-1/src/crawler/datastarpocplus.py", line 47, in get_cves
    response = requests.post(
  File "/usr/local/python3/lib/python3.8/site-packages/requests/api.py", line 116, in post
    return request('post', url, data=data, json=json, **kwargs)
  File "/usr/local/python3/lib/python3.8/site-packages/requests/api.py", line 60, in request
    return session.request(method=method, url=url, **kwargs)
  File "/usr/local/python3/lib/python3.8/site-packages/requests/sessions.py", line 533, in request
    resp = self.send(prep, **send_kwargs)
  File "/usr/local/python3/lib/python3.8/site-packages/requests/sessions.py", line 646, in send
    r = adapter.send(request, **kwargs)
  File "/usr/local/python3/lib/python3.8/site-packages/requests/adapters.py", line 529, in send
    raise ReadTimeout(e, request=request)
requests.exceptions.ReadTimeout: HTTPSConnectionPool(host='poc.shuziguanxing.com', port=443): Read timed out. (read timeout=60)
2022-04-27 11:11:52 [ERROR] : Traceback (most recent call last):
  File "/usr/local/python3/lib/python3.8/site-packages/urllib3/connectionpool.py", line 381, in _make_request
    self._validate_conn(conn)
  File "/usr/local/python3/lib/python3.8/site-packages/urllib3/connectionpool.py", line 978, in _validate_conn
    conn.connect()
  File "/usr/local/python3/lib/python3.8/site-packages/urllib3/connection.py", line 362, in connect
    self.sock = ssl_wrap_socket(
  File "/usr/local/python3/lib/python3.8/site-packages/urllib3/util/ssl_.py", line 386, in ssl_wrap_socket
    return context.wrap_socket(sock, server_hostname=server_hostname)
  File "/usr/local/python3/lib/python3.8/ssl.py", line 500, in wrap_socket
    return self.sslsocket_class._create(
  File "/usr/local/python3/lib/python3.8/ssl.py", line 1040, in _create
    self.do_handshake()
  File "/usr/local/python3/lib/python3.8/ssl.py", line 1309, in do_handshake
    self._sslobj.do_handshake()
socket.timeout: _ssl.c:1091: The handshake operation timed out

During handling of the above exception, another exception occurred:

Traceback (most recent call last):
  File "/usr/local/python3/lib/python3.8/site-packages/requests/adapters.py", line 439, in send
    resp = conn.urlopen(
  File "/usr/local/python3/lib/python3.8/site-packages/urllib3/connectionpool.py", line 726, in urlopen
    retries = retries.increment(
  File "/usr/local/python3/lib/python3.8/site-packages/urllib3/util/retry.py", line 410, in increment
    raise six.reraise(type(error), error, _stacktrace)
  File "/usr/local/python3/lib/python3.8/site-packages/urllib3/packages/six.py", line 735, in reraise
    raise value
  File "/usr/local/python3/lib/python3.8/site-packages/urllib3/connectionpool.py", line 670, in urlopen
    httplib_response = self._make_request(
  File "/usr/local/python3/lib/python3.8/site-packages/urllib3/connectionpool.py", line 384, in _make_request
    self._raise_timeout(err=e, url=url, timeout_value=conn.timeout)
  File "/usr/local/python3/lib/python3.8/site-packages/urllib3/connectionpool.py", line 335, in _raise_timeout
    raise ReadTimeoutError(
urllib3.exceptions.ReadTimeoutError: HTTPSConnectionPool(host='poc.shuziguanxing.com', port=443): Read timed out. (read timeout=60)

During handling of the above exception, another exception occurred:

Traceback (most recent call last):
  File "/root/project/threat-broadcast-1/src/crawler/_base_crawler.py", line 62, in cves
    new_cves = self.get_cves()
  File "/root/project/threat-broadcast-1/src/crawler/datastarpocplus.py", line 47, in get_cves
    response = requests.post(
  File "/usr/local/python3/lib/python3.8/site-packages/requests/api.py", line 116, in post
    return request('post', url, data=data, json=json, **kwargs)
  File "/usr/local/python3/lib/python3.8/site-packages/requests/api.py", line 60, in request
    return session.request(method=method, url=url, **kwargs)
  File "/usr/local/python3/lib/python3.8/site-packages/requests/sessions.py", line 533, in request
    resp = self.send(prep, **send_kwargs)
  File "/usr/local/python3/lib/python3.8/site-packages/requests/sessions.py", line 646, in send
    r = adapter.send(request, **kwargs)
  File "/usr/local/python3/lib/python3.8/site-packages/requests/adapters.py", line 529, in send
    raise ReadTimeout(e, request=request)
requests.exceptions.ReadTimeout: HTTPSConnectionPool(host='poc.shuziguanxing.com', port=443): Read timed out. (read timeout=60)
Traceback (most recent call last):
  File "/usr/local/python3/lib/python3.8/site-packages/urllib3/connectionpool.py", line 381, in _make_request
    self._validate_conn(conn)
  File "/usr/local/python3/lib/python3.8/site-packages/urllib3/connectionpool.py", line 978, in _validate_conn
    conn.connect()
  File "/usr/local/python3/lib/python3.8/site-packages/urllib3/connection.py", line 362, in connect
    self.sock = ssl_wrap_socket(
  File "/usr/local/python3/lib/python3.8/site-packages/urllib3/util/ssl_.py", line 386, in ssl_wrap_socket
    return context.wrap_socket(sock, server_hostname=server_hostname)
  File "/usr/local/python3/lib/python3.8/ssl.py", line 500, in wrap_socket
    return self.sslsocket_class._create(
  File "/usr/local/python3/lib/python3.8/ssl.py", line 1040, in _create
    self.do_handshake()
  File "/usr/local/python3/lib/python3.8/ssl.py", line 1309, in do_handshake
    self._sslobj.do_handshake()
socket.timeout: _ssl.c:1091: The handshake operation timed out

During handling of the above exception, another exception occurred:

Traceback (most recent call last):
  File "/usr/local/python3/lib/python3.8/site-packages/requests/adapters.py", line 439, in send
    resp = conn.urlopen(
  File "/usr/local/python3/lib/python3.8/site-packages/urllib3/connectionpool.py", line 726, in urlopen
    retries = retries.increment(
  File "/usr/local/python3/lib/python3.8/site-packages/urllib3/util/retry.py", line 410, in increment
    raise six.reraise(type(error), error, _stacktrace)
  File "/usr/local/python3/lib/python3.8/site-packages/urllib3/packages/six.py", line 735, in reraise
    raise value
  File "/usr/local/python3/lib/python3.8/site-packages/urllib3/connectionpool.py", line 670, in urlopen
    httplib_response = self._make_request(
  File "/usr/local/python3/lib/python3.8/site-packages/urllib3/connectionpool.py", line 384, in _make_request
    self._raise_timeout(err=e, url=url, timeout_value=conn.timeout)
  File "/usr/local/python3/lib/python3.8/site-packages/urllib3/connectionpool.py", line 335, in _raise_timeout
    raise ReadTimeoutError(
urllib3.exceptions.ReadTimeoutError: HTTPSConnectionPool(host='poc.shuziguanxing.com', port=443): Read timed out. (read timeout=60)

During handling of the above exception, another exception occurred:

Traceback (most recent call last):
  File "/root/project/threat-broadcast-1/src/crawler/_base_crawler.py", line 62, in cves
    new_cves = self.get_cves()
  File "/root/project/threat-broadcast-1/src/crawler/datastarpocplus.py", line 47, in get_cves
    response = requests.post(
  File "/usr/local/python3/lib/python3.8/site-packages/requests/api.py", line 116, in post
    return request('post', url, data=data, json=json, **kwargs)
  File "/usr/local/python3/lib/python3.8/site-packages/requests/api.py", line 60, in request
    return session.request(method=method, url=url, **kwargs)
  File "/usr/local/python3/lib/python3.8/site-packages/requests/sessions.py", line 533, in request
    resp = self.send(prep, **send_kwargs)
  File "/usr/local/python3/lib/python3.8/site-packages/requests/sessions.py", line 646, in send
    r = adapter.send(request, **kwargs)
  File "/usr/local/python3/lib/python3.8/site-packages/requests/adapters.py", line 529, in send
    raise ReadTimeout(e, request=request)
requests.exceptions.ReadTimeout: HTTPSConnectionPool(host='poc.shuziguanxing.com', port=443): Read timed out. (read timeout=60)
2022-05-01 02:23:18 [ERROR] : 获取 Issue 的邮箱失败（国内 GraphQL 接口不稳定）
Traceback (most recent call last):
  File "/home/runner/work/threat-broadcast-1/threat-broadcast-1/src/notice/mail.py", line 110, in load_issue_receivers
    issues = _git.query_issues(gtk)
  File "/home/runner/work/threat-broadcast-1/threat-broadcast-1/src/utils/_git.py", line 43, in query_issues
    data = client.execute(
  File "/opt/hostedtoolcache/Python/3.8.12/x64/lib/python3.8/site-packages/python_graphql_client/graphql_client.py", line 53, in execute
    result.raise_for_status()
  File "/opt/hostedtoolcache/Python/3.8.12/x64/lib/python3.8/site-packages/requests/models.py", line 940, in raise_for_status
    raise HTTPError(http_error_msg, response=self)
requests.exceptions.HTTPError: 401 Client Error: Unauthorized for url: https://api.github.com/graphql
2022-05-01 02:23:18 [ERROR] : Traceback (most recent call last):
  File "/home/runner/work/threat-broadcast-1/threat-broadcast-1/src/notice/mail.py", line 110, in load_issue_receivers
    issues = _git.query_issues(gtk)
  File "/home/runner/work/threat-broadcast-1/threat-broadcast-1/src/utils/_git.py", line 43, in query_issues
    data = client.execute(
  File "/opt/hostedtoolcache/Python/3.8.12/x64/lib/python3.8/site-packages/python_graphql_client/graphql_client.py", line 53, in execute
    result.raise_for_status()
  File "/opt/hostedtoolcache/Python/3.8.12/x64/lib/python3.8/site-packages/requests/models.py", line 940, in raise_for_status
    raise HTTPError(http_error_msg, response=self)
requests.exceptions.HTTPError: 401 Client Error: Unauthorized for url: https://api.github.com/graphql
Traceback (most recent call last):
  File "/home/runner/work/threat-broadcast-1/threat-broadcast-1/src/notice/mail.py", line 110, in load_issue_receivers
    issues = _git.query_issues(gtk)
  File "/home/runner/work/threat-broadcast-1/threat-broadcast-1/src/utils/_git.py", line 43, in query_issues
    data = client.execute(
  File "/opt/hostedtoolcache/Python/3.8.12/x64/lib/python3.8/site-packages/python_graphql_client/graphql_client.py", line 53, in execute
    result.raise_for_status()
  File "/opt/hostedtoolcache/Python/3.8.12/x64/lib/python3.8/site-packages/requests/models.py", line 940, in raise_for_status
    raise HTTPError(http_error_msg, response=self)
requests.exceptions.HTTPError: 401 Client Error: Unauthorized for url: https://api.github.com/graphql
2022-05-01 03:50:30 [ERROR] : 获取 Issue 的邮箱失败（国内 GraphQL 接口不稳定）
Traceback (most recent call last):
  File "/home/runner/work/threat-broadcast-1/threat-broadcast-1/src/notice/mail.py", line 110, in load_issue_receivers
    issues = _git.query_issues(gtk)
  File "/home/runner/work/threat-broadcast-1/threat-broadcast-1/src/utils/_git.py", line 43, in query_issues
    data = client.execute(
  File "/opt/hostedtoolcache/Python/3.8.12/x64/lib/python3.8/site-packages/python_graphql_client/graphql_client.py", line 53, in execute
    result.raise_for_status()
  File "/opt/hostedtoolcache/Python/3.8.12/x64/lib/python3.8/site-packages/requests/models.py", line 940, in raise_for_status
    raise HTTPError(http_error_msg, response=self)
requests.exceptions.HTTPError: 401 Client Error: Unauthorized for url: https://api.github.com/graphql
2022-05-01 03:50:30 [ERROR] : Traceback (most recent call last):
  File "/home/runner/work/threat-broadcast-1/threat-broadcast-1/src/notice/mail.py", line 110, in load_issue_receivers
    issues = _git.query_issues(gtk)
  File "/home/runner/work/threat-broadcast-1/threat-broadcast-1/src/utils/_git.py", line 43, in query_issues
    data = client.execute(
  File "/opt/hostedtoolcache/Python/3.8.12/x64/lib/python3.8/site-packages/python_graphql_client/graphql_client.py", line 53, in execute
    result.raise_for_status()
  File "/opt/hostedtoolcache/Python/3.8.12/x64/lib/python3.8/site-packages/requests/models.py", line 940, in raise_for_status
    raise HTTPError(http_error_msg, response=self)
requests.exceptions.HTTPError: 401 Client Error: Unauthorized for url: https://api.github.com/graphql
Traceback (most recent call last):
  File "/home/runner/work/threat-broadcast-1/threat-broadcast-1/src/notice/mail.py", line 110, in load_issue_receivers
    issues = _git.query_issues(gtk)
  File "/home/runner/work/threat-broadcast-1/threat-broadcast-1/src/utils/_git.py", line 43, in query_issues
    data = client.execute(
  File "/opt/hostedtoolcache/Python/3.8.12/x64/lib/python3.8/site-packages/python_graphql_client/graphql_client.py", line 53, in execute
    result.raise_for_status()
  File "/opt/hostedtoolcache/Python/3.8.12/x64/lib/python3.8/site-packages/requests/models.py", line 940, in raise_for_status
    raise HTTPError(http_error_msg, response=self)
requests.exceptions.HTTPError: 401 Client Error: Unauthorized for url: https://api.github.com/graphql
2022-05-01 04:26:24 [ERROR] : 获取 Issue 的邮箱失败（国内 GraphQL 接口不稳定）
Traceback (most recent call last):
  File "/home/runner/work/threat-broadcast-1/threat-broadcast-1/src/notice/mail.py", line 110, in load_issue_receivers
    issues = _git.query_issues(gtk)
  File "/home/runner/work/threat-broadcast-1/threat-broadcast-1/src/utils/_git.py", line 43, in query_issues
    data = client.execute(
  File "/opt/hostedtoolcache/Python/3.8.12/x64/lib/python3.8/site-packages/python_graphql_client/graphql_client.py", line 53, in execute
    result.raise_for_status()
  File "/opt/hostedtoolcache/Python/3.8.12/x64/lib/python3.8/site-packages/requests/models.py", line 940, in raise_for_status
    raise HTTPError(http_error_msg, response=self)
requests.exceptions.HTTPError: 401 Client Error: Unauthorized for url: https://api.github.com/graphql
2022-05-01 04:26:24 [ERROR] : Traceback (most recent call last):
  File "/home/runner/work/threat-broadcast-1/threat-broadcast-1/src/notice/mail.py", line 110, in load_issue_receivers
    issues = _git.query_issues(gtk)
  File "/home/runner/work/threat-broadcast-1/threat-broadcast-1/src/utils/_git.py", line 43, in query_issues
    data = client.execute(
  File "/opt/hostedtoolcache/Python/3.8.12/x64/lib/python3.8/site-packages/python_graphql_client/graphql_client.py", line 53, in execute
    result.raise_for_status()
  File "/opt/hostedtoolcache/Python/3.8.12/x64/lib/python3.8/site-packages/requests/models.py", line 940, in raise_for_status
    raise HTTPError(http_error_msg, response=self)
requests.exceptions.HTTPError: 401 Client Error: Unauthorized for url: https://api.github.com/graphql
Traceback (most recent call last):
  File "/home/runner/work/threat-broadcast-1/threat-broadcast-1/src/notice/mail.py", line 110, in load_issue_receivers
    issues = _git.query_issues(gtk)
  File "/home/runner/work/threat-broadcast-1/threat-broadcast-1/src/utils/_git.py", line 43, in query_issues
    data = client.execute(
  File "/opt/hostedtoolcache/Python/3.8.12/x64/lib/python3.8/site-packages/python_graphql_client/graphql_client.py", line 53, in execute
    result.raise_for_status()
  File "/opt/hostedtoolcache/Python/3.8.12/x64/lib/python3.8/site-packages/requests/models.py", line 940, in raise_for_status
    raise HTTPError(http_error_msg, response=self)
requests.exceptions.HTTPError: 401 Client Error: Unauthorized for url: https://api.github.com/graphql
2022-05-01 05:03:33 [ERROR] : 获取 Issue 的邮箱失败（国内 GraphQL 接口不稳定）
Traceback (most recent call last):
  File "/home/runner/work/threat-broadcast-1/threat-broadcast-1/src/notice/mail.py", line 110, in load_issue_receivers
    issues = _git.query_issues(gtk)
  File "/home/runner/work/threat-broadcast-1/threat-broadcast-1/src/utils/_git.py", line 43, in query_issues
    data = client.execute(
  File "/opt/hostedtoolcache/Python/3.8.12/x64/lib/python3.8/site-packages/python_graphql_client/graphql_client.py", line 53, in execute
    result.raise_for_status()
  File "/opt/hostedtoolcache/Python/3.8.12/x64/lib/python3.8/site-packages/requests/models.py", line 940, in raise_for_status
    raise HTTPError(http_error_msg, response=self)
requests.exceptions.HTTPError: 401 Client Error: Unauthorized for url: https://api.github.com/graphql
2022-05-01 05:03:33 [ERROR] : Traceback (most recent call last):
  File "/home/runner/work/threat-broadcast-1/threat-broadcast-1/src/notice/mail.py", line 110, in load_issue_receivers
    issues = _git.query_issues(gtk)
  File "/home/runner/work/threat-broadcast-1/threat-broadcast-1/src/utils/_git.py", line 43, in query_issues
    data = client.execute(
  File "/opt/hostedtoolcache/Python/3.8.12/x64/lib/python3.8/site-packages/python_graphql_client/graphql_client.py", line 53, in execute
    result.raise_for_status()
  File "/opt/hostedtoolcache/Python/3.8.12/x64/lib/python3.8/site-packages/requests/models.py", line 940, in raise_for_status
    raise HTTPError(http_error_msg, response=self)
requests.exceptions.HTTPError: 401 Client Error: Unauthorized for url: https://api.github.com/graphql
Traceback (most recent call last):
  File "/home/runner/work/threat-broadcast-1/threat-broadcast-1/src/notice/mail.py", line 110, in load_issue_receivers
    issues = _git.query_issues(gtk)
  File "/home/runner/work/threat-broadcast-1/threat-broadcast-1/src/utils/_git.py", line 43, in query_issues
    data = client.execute(
  File "/opt/hostedtoolcache/Python/3.8.12/x64/lib/python3.8/site-packages/python_graphql_client/graphql_client.py", line 53, in execute
    result.raise_for_status()
  File "/opt/hostedtoolcache/Python/3.8.12/x64/lib/python3.8/site-packages/requests/models.py", line 940, in raise_for_status
    raise HTTPError(http_error_msg, response=self)
requests.exceptions.HTTPError: 401 Client Error: Unauthorized for url: https://api.github.com/graphql
2022-05-01 05:31:24 [ERROR] : 获取 Issue 的邮箱失败（国内 GraphQL 接口不稳定）
Traceback (most recent call last):
  File "/home/runner/work/threat-broadcast-1/threat-broadcast-1/src/notice/mail.py", line 110, in load_issue_receivers
    issues = _git.query_issues(gtk)
  File "/home/runner/work/threat-broadcast-1/threat-broadcast-1/src/utils/_git.py", line 43, in query_issues
    data = client.execute(
  File "/opt/hostedtoolcache/Python/3.8.12/x64/lib/python3.8/site-packages/python_graphql_client/graphql_client.py", line 53, in execute
    result.raise_for_status()
  File "/opt/hostedtoolcache/Python/3.8.12/x64/lib/python3.8/site-packages/requests/models.py", line 940, in raise_for_status
    raise HTTPError(http_error_msg, response=self)
requests.exceptions.HTTPError: 401 Client Error: Unauthorized for url: https://api.github.com/graphql
2022-05-01 05:31:24 [ERROR] : Traceback (most recent call last):
  File "/home/runner/work/threat-broadcast-1/threat-broadcast-1/src/notice/mail.py", line 110, in load_issue_receivers
    issues = _git.query_issues(gtk)
  File "/home/runner/work/threat-broadcast-1/threat-broadcast-1/src/utils/_git.py", line 43, in query_issues
    data = client.execute(
  File "/opt/hostedtoolcache/Python/3.8.12/x64/lib/python3.8/site-packages/python_graphql_client/graphql_client.py", line 53, in execute
    result.raise_for_status()
  File "/opt/hostedtoolcache/Python/3.8.12/x64/lib/python3.8/site-packages/requests/models.py", line 940, in raise_for_status
    raise HTTPError(http_error_msg, response=self)
requests.exceptions.HTTPError: 401 Client Error: Unauthorized for url: https://api.github.com/graphql
Traceback (most recent call last):
  File "/home/runner/work/threat-broadcast-1/threat-broadcast-1/src/notice/mail.py", line 110, in load_issue_receivers
    issues = _git.query_issues(gtk)
  File "/home/runner/work/threat-broadcast-1/threat-broadcast-1/src/utils/_git.py", line 43, in query_issues
    data = client.execute(
  File "/opt/hostedtoolcache/Python/3.8.12/x64/lib/python3.8/site-packages/python_graphql_client/graphql_client.py", line 53, in execute
    result.raise_for_status()
  File "/opt/hostedtoolcache/Python/3.8.12/x64/lib/python3.8/site-packages/requests/models.py", line 940, in raise_for_status
    raise HTTPError(http_error_msg, response=self)
requests.exceptions.HTTPError: 401 Client Error: Unauthorized for url: https://api.github.com/graphql
2022-05-01 05:46:28 [ERROR] : 获取 Issue 的邮箱失败（国内 GraphQL 接口不稳定）
Traceback (most recent call last):
  File "/home/runner/work/threat-broadcast-1/threat-broadcast-1/src/notice/mail.py", line 110, in load_issue_receivers
    issues = _git.query_issues(gtk)
  File "/home/runner/work/threat-broadcast-1/threat-broadcast-1/src/utils/_git.py", line 43, in query_issues
    data = client.execute(
  File "/opt/hostedtoolcache/Python/3.8.12/x64/lib/python3.8/site-packages/python_graphql_client/graphql_client.py", line 53, in execute
    result.raise_for_status()
  File "/opt/hostedtoolcache/Python/3.8.12/x64/lib/python3.8/site-packages/requests/models.py", line 940, in raise_for_status
    raise HTTPError(http_error_msg, response=self)
requests.exceptions.HTTPError: 401 Client Error: Unauthorized for url: https://api.github.com/graphql
2022-05-01 05:46:28 [ERROR] : Traceback (most recent call last):
  File "/home/runner/work/threat-broadcast-1/threat-broadcast-1/src/notice/mail.py", line 110, in load_issue_receivers
    issues = _git.query_issues(gtk)
  File "/home/runner/work/threat-broadcast-1/threat-broadcast-1/src/utils/_git.py", line 43, in query_issues
    data = client.execute(
  File "/opt/hostedtoolcache/Python/3.8.12/x64/lib/python3.8/site-packages/python_graphql_client/graphql_client.py", line 53, in execute
    result.raise_for_status()
  File "/opt/hostedtoolcache/Python/3.8.12/x64/lib/python3.8/site-packages/requests/models.py", line 940, in raise_for_status
    raise HTTPError(http_error_msg, response=self)
requests.exceptions.HTTPError: 401 Client Error: Unauthorized for url: https://api.github.com/graphql
Traceback (most recent call last):
  File "/home/runner/work/threat-broadcast-1/threat-broadcast-1/src/notice/mail.py", line 110, in load_issue_receivers
    issues = _git.query_issues(gtk)
  File "/home/runner/work/threat-broadcast-1/threat-broadcast-1/src/utils/_git.py", line 43, in query_issues
    data = client.execute(
  File "/opt/hostedtoolcache/Python/3.8.12/x64/lib/python3.8/site-packages/python_graphql_client/graphql_client.py", line 53, in execute
    result.raise_for_status()
  File "/opt/hostedtoolcache/Python/3.8.12/x64/lib/python3.8/site-packages/requests/models.py", line 940, in raise_for_status
    raise HTTPError(http_error_msg, response=self)
requests.exceptions.HTTPError: 401 Client Error: Unauthorized for url: https://api.github.com/graphql
2022-05-01 05:58:54 [ERROR] : 获取 Issue 的邮箱失败（国内 GraphQL 接口不稳定）
Traceback (most recent call last):
  File "/home/runner/work/threat-broadcast-1/threat-broadcast-1/src/notice/mail.py", line 110, in load_issue_receivers
    issues = _git.query_issues(gtk)
  File "/home/runner/work/threat-broadcast-1/threat-broadcast-1/src/utils/_git.py", line 43, in query_issues
    data = client.execute(
  File "/opt/hostedtoolcache/Python/3.8.12/x64/lib/python3.8/site-packages/python_graphql_client/graphql_client.py", line 53, in execute
    result.raise_for_status()
  File "/opt/hostedtoolcache/Python/3.8.12/x64/lib/python3.8/site-packages/requests/models.py", line 940, in raise_for_status
    raise HTTPError(http_error_msg, response=self)
requests.exceptions.HTTPError: 401 Client Error: Unauthorized for url: https://api.github.com/graphql
2022-05-01 05:58:54 [ERROR] : Traceback (most recent call last):
  File "/home/runner/work/threat-broadcast-1/threat-broadcast-1/src/notice/mail.py", line 110, in load_issue_receivers
    issues = _git.query_issues(gtk)
  File "/home/runner/work/threat-broadcast-1/threat-broadcast-1/src/utils/_git.py", line 43, in query_issues
    data = client.execute(
  File "/opt/hostedtoolcache/Python/3.8.12/x64/lib/python3.8/site-packages/python_graphql_client/graphql_client.py", line 53, in execute
    result.raise_for_status()
  File "/opt/hostedtoolcache/Python/3.8.12/x64/lib/python3.8/site-packages/requests/models.py", line 940, in raise_for_status
    raise HTTPError(http_error_msg, response=self)
requests.exceptions.HTTPError: 401 Client Error: Unauthorized for url: https://api.github.com/graphql
Traceback (most recent call last):
  File "/home/runner/work/threat-broadcast-1/threat-broadcast-1/src/notice/mail.py", line 110, in load_issue_receivers
    issues = _git.query_issues(gtk)
  File "/home/runner/work/threat-broadcast-1/threat-broadcast-1/src/utils/_git.py", line 43, in query_issues
    data = client.execute(
  File "/opt/hostedtoolcache/Python/3.8.12/x64/lib/python3.8/site-packages/python_graphql_client/graphql_client.py", line 53, in execute
    result.raise_for_status()
  File "/opt/hostedtoolcache/Python/3.8.12/x64/lib/python3.8/site-packages/requests/models.py", line 940, in raise_for_status
    raise HTTPError(http_error_msg, response=self)
requests.exceptions.HTTPError: 401 Client Error: Unauthorized for url: https://api.github.com/graphql
2022-05-01 06:31:15 [ERROR] : 获取 Issue 的邮箱失败（国内 GraphQL 接口不稳定）
Traceback (most recent call last):
  File "/home/runner/work/threat-broadcast-1/threat-broadcast-1/src/notice/mail.py", line 110, in load_issue_receivers
    issues = _git.query_issues(gtk)
  File "/home/runner/work/threat-broadcast-1/threat-broadcast-1/src/utils/_git.py", line 43, in query_issues
    data = client.execute(
  File "/opt/hostedtoolcache/Python/3.8.12/x64/lib/python3.8/site-packages/python_graphql_client/graphql_client.py", line 53, in execute
    result.raise_for_status()
  File "/opt/hostedtoolcache/Python/3.8.12/x64/lib/python3.8/site-packages/requests/models.py", line 940, in raise_for_status
    raise HTTPError(http_error_msg, response=self)
requests.exceptions.HTTPError: 401 Client Error: Unauthorized for url: https://api.github.com/graphql
2022-05-01 06:31:15 [ERROR] : Traceback (most recent call last):
  File "/home/runner/work/threat-broadcast-1/threat-broadcast-1/src/notice/mail.py", line 110, in load_issue_receivers
    issues = _git.query_issues(gtk)
  File "/home/runner/work/threat-broadcast-1/threat-broadcast-1/src/utils/_git.py", line 43, in query_issues
    data = client.execute(
  File "/opt/hostedtoolcache/Python/3.8.12/x64/lib/python3.8/site-packages/python_graphql_client/graphql_client.py", line 53, in execute
    result.raise_for_status()
  File "/opt/hostedtoolcache/Python/3.8.12/x64/lib/python3.8/site-packages/requests/models.py", line 940, in raise_for_status
    raise HTTPError(http_error_msg, response=self)
requests.exceptions.HTTPError: 401 Client Error: Unauthorized for url: https://api.github.com/graphql
Traceback (most recent call last):
  File "/home/runner/work/threat-broadcast-1/threat-broadcast-1/src/notice/mail.py", line 110, in load_issue_receivers
    issues = _git.query_issues(gtk)
  File "/home/runner/work/threat-broadcast-1/threat-broadcast-1/src/utils/_git.py", line 43, in query_issues
    data = client.execute(
  File "/opt/hostedtoolcache/Python/3.8.12/x64/lib/python3.8/site-packages/python_graphql_client/graphql_client.py", line 53, in execute
    result.raise_for_status()
  File "/opt/hostedtoolcache/Python/3.8.12/x64/lib/python3.8/site-packages/requests/models.py", line 940, in raise_for_status
    raise HTTPError(http_error_msg, response=self)
requests.exceptions.HTTPError: 401 Client Error: Unauthorized for url: https://api.github.com/graphql
2022-05-01 06:52:57 [ERROR] : 获取 Issue 的邮箱失败（国内 GraphQL 接口不稳定）
Traceback (most recent call last):
  File "/home/runner/work/threat-broadcast-1/threat-broadcast-1/src/notice/mail.py", line 110, in load_issue_receivers
    issues = _git.query_issues(gtk)
  File "/home/runner/work/threat-broadcast-1/threat-broadcast-1/src/utils/_git.py", line 43, in query_issues
    data = client.execute(
  File "/opt/hostedtoolcache/Python/3.8.12/x64/lib/python3.8/site-packages/python_graphql_client/graphql_client.py", line 53, in execute
    result.raise_for_status()
  File "/opt/hostedtoolcache/Python/3.8.12/x64/lib/python3.8/site-packages/requests/models.py", line 940, in raise_for_status
    raise HTTPError(http_error_msg, response=self)
requests.exceptions.HTTPError: 401 Client Error: Unauthorized for url: https://api.github.com/graphql
2022-05-01 06:52:57 [ERROR] : Traceback (most recent call last):
  File "/home/runner/work/threat-broadcast-1/threat-broadcast-1/src/notice/mail.py", line 110, in load_issue_receivers
    issues = _git.query_issues(gtk)
  File "/home/runner/work/threat-broadcast-1/threat-broadcast-1/src/utils/_git.py", line 43, in query_issues
    data = client.execute(
  File "/opt/hostedtoolcache/Python/3.8.12/x64/lib/python3.8/site-packages/python_graphql_client/graphql_client.py", line 53, in execute
    result.raise_for_status()
  File "/opt/hostedtoolcache/Python/3.8.12/x64/lib/python3.8/site-packages/requests/models.py", line 940, in raise_for_status
    raise HTTPError(http_error_msg, response=self)
requests.exceptions.HTTPError: 401 Client Error: Unauthorized for url: https://api.github.com/graphql
Traceback (most recent call last):
  File "/home/runner/work/threat-broadcast-1/threat-broadcast-1/src/notice/mail.py", line 110, in load_issue_receivers
    issues = _git.query_issues(gtk)
  File "/home/runner/work/threat-broadcast-1/threat-broadcast-1/src/utils/_git.py", line 43, in query_issues
    data = client.execute(
  File "/opt/hostedtoolcache/Python/3.8.12/x64/lib/python3.8/site-packages/python_graphql_client/graphql_client.py", line 53, in execute
    result.raise_for_status()
  File "/opt/hostedtoolcache/Python/3.8.12/x64/lib/python3.8/site-packages/requests/models.py", line 940, in raise_for_status
    raise HTTPError(http_error_msg, response=self)
requests.exceptions.HTTPError: 401 Client Error: Unauthorized for url: https://api.github.com/graphql
2022-05-01 07:15:33 [ERROR] : 获取 Issue 的邮箱失败（国内 GraphQL 接口不稳定）
Traceback (most recent call last):
  File "/home/runner/work/threat-broadcast-1/threat-broadcast-1/src/notice/mail.py", line 110, in load_issue_receivers
    issues = _git.query_issues(gtk)
  File "/home/runner/work/threat-broadcast-1/threat-broadcast-1/src/utils/_git.py", line 43, in query_issues
    data = client.execute(
  File "/opt/hostedtoolcache/Python/3.8.12/x64/lib/python3.8/site-packages/python_graphql_client/graphql_client.py", line 53, in execute
    result.raise_for_status()
  File "/opt/hostedtoolcache/Python/3.8.12/x64/lib/python3.8/site-packages/requests/models.py", line 940, in raise_for_status
    raise HTTPError(http_error_msg, response=self)
requests.exceptions.HTTPError: 401 Client Error: Unauthorized for url: https://api.github.com/graphql
2022-05-01 07:15:33 [ERROR] : Traceback (most recent call last):
  File "/home/runner/work/threat-broadcast-1/threat-broadcast-1/src/notice/mail.py", line 110, in load_issue_receivers
    issues = _git.query_issues(gtk)
  File "/home/runner/work/threat-broadcast-1/threat-broadcast-1/src/utils/_git.py", line 43, in query_issues
    data = client.execute(
  File "/opt/hostedtoolcache/Python/3.8.12/x64/lib/python3.8/site-packages/python_graphql_client/graphql_client.py", line 53, in execute
    result.raise_for_status()
  File "/opt/hostedtoolcache/Python/3.8.12/x64/lib/python3.8/site-packages/requests/models.py", line 940, in raise_for_status
    raise HTTPError(http_error_msg, response=self)
requests.exceptions.HTTPError: 401 Client Error: Unauthorized for url: https://api.github.com/graphql
Traceback (most recent call last):
  File "/home/runner/work/threat-broadcast-1/threat-broadcast-1/src/notice/mail.py", line 110, in load_issue_receivers
    issues = _git.query_issues(gtk)
  File "/home/runner/work/threat-broadcast-1/threat-broadcast-1/src/utils/_git.py", line 43, in query_issues
    data = client.execute(
  File "/opt/hostedtoolcache/Python/3.8.12/x64/lib/python3.8/site-packages/python_graphql_client/graphql_client.py", line 53, in execute
    result.raise_for_status()
  File "/opt/hostedtoolcache/Python/3.8.12/x64/lib/python3.8/site-packages/requests/models.py", line 940, in raise_for_status
    raise HTTPError(http_error_msg, response=self)
requests.exceptions.HTTPError: 401 Client Error: Unauthorized for url: https://api.github.com/graphql
2022-05-01 07:32:24 [ERROR] : 获取 Issue 的邮箱失败（国内 GraphQL 接口不稳定）
Traceback (most recent call last):
  File "/home/runner/work/threat-broadcast-1/threat-broadcast-1/src/notice/mail.py", line 110, in load_issue_receivers
    issues = _git.query_issues(gtk)
  File "/home/runner/work/threat-broadcast-1/threat-broadcast-1/src/utils/_git.py", line 43, in query_issues
    data = client.execute(
  File "/opt/hostedtoolcache/Python/3.8.12/x64/lib/python3.8/site-packages/python_graphql_client/graphql_client.py", line 53, in execute
    result.raise_for_status()
  File "/opt/hostedtoolcache/Python/3.8.12/x64/lib/python3.8/site-packages/requests/models.py", line 940, in raise_for_status
    raise HTTPError(http_error_msg, response=self)
requests.exceptions.HTTPError: 401 Client Error: Unauthorized for url: https://api.github.com/graphql
2022-05-01 07:32:24 [ERROR] : Traceback (most recent call last):
  File "/home/runner/work/threat-broadcast-1/threat-broadcast-1/src/notice/mail.py", line 110, in load_issue_receivers
    issues = _git.query_issues(gtk)
  File "/home/runner/work/threat-broadcast-1/threat-broadcast-1/src/utils/_git.py", line 43, in query_issues
    data = client.execute(
  File "/opt/hostedtoolcache/Python/3.8.12/x64/lib/python3.8/site-packages/python_graphql_client/graphql_client.py", line 53, in execute
    result.raise_for_status()
  File "/opt/hostedtoolcache/Python/3.8.12/x64/lib/python3.8/site-packages/requests/models.py", line 940, in raise_for_status
    raise HTTPError(http_error_msg, response=self)
requests.exceptions.HTTPError: 401 Client Error: Unauthorized for url: https://api.github.com/graphql
Traceback (most recent call last):
  File "/home/runner/work/threat-broadcast-1/threat-broadcast-1/src/notice/mail.py", line 110, in load_issue_receivers
    issues = _git.query_issues(gtk)
  File "/home/runner/work/threat-broadcast-1/threat-broadcast-1/src/utils/_git.py", line 43, in query_issues
    data = client.execute(
  File "/opt/hostedtoolcache/Python/3.8.12/x64/lib/python3.8/site-packages/python_graphql_client/graphql_client.py", line 53, in execute
    result.raise_for_status()
  File "/opt/hostedtoolcache/Python/3.8.12/x64/lib/python3.8/site-packages/requests/models.py", line 940, in raise_for_status
    raise HTTPError(http_error_msg, response=self)
requests.exceptions.HTTPError: 401 Client Error: Unauthorized for url: https://api.github.com/graphql
2022-05-01 07:44:46 [ERROR] : 获取 Issue 的邮箱失败（国内 GraphQL 接口不稳定）
Traceback (most recent call last):
  File "/home/runner/work/threat-broadcast-1/threat-broadcast-1/src/notice/mail.py", line 110, in load_issue_receivers
    issues = _git.query_issues(gtk)
  File "/home/runner/work/threat-broadcast-1/threat-broadcast-1/src/utils/_git.py", line 43, in query_issues
    data = client.execute(
  File "/opt/hostedtoolcache/Python/3.8.12/x64/lib/python3.8/site-packages/python_graphql_client/graphql_client.py", line 53, in execute
    result.raise_for_status()
  File "/opt/hostedtoolcache/Python/3.8.12/x64/lib/python3.8/site-packages/requests/models.py", line 940, in raise_for_status
    raise HTTPError(http_error_msg, response=self)
requests.exceptions.HTTPError: 401 Client Error: Unauthorized for url: https://api.github.com/graphql
2022-05-01 07:44:46 [ERROR] : Traceback (most recent call last):
  File "/home/runner/work/threat-broadcast-1/threat-broadcast-1/src/notice/mail.py", line 110, in load_issue_receivers
    issues = _git.query_issues(gtk)
  File "/home/runner/work/threat-broadcast-1/threat-broadcast-1/src/utils/_git.py", line 43, in query_issues
    data = client.execute(
  File "/opt/hostedtoolcache/Python/3.8.12/x64/lib/python3.8/site-packages/python_graphql_client/graphql_client.py", line 53, in execute
    result.raise_for_status()
  File "/opt/hostedtoolcache/Python/3.8.12/x64/lib/python3.8/site-packages/requests/models.py", line 940, in raise_for_status
    raise HTTPError(http_error_msg, response=self)
requests.exceptions.HTTPError: 401 Client Error: Unauthorized for url: https://api.github.com/graphql
Traceback (most recent call last):
  File "/home/runner/work/threat-broadcast-1/threat-broadcast-1/src/notice/mail.py", line 110, in load_issue_receivers
    issues = _git.query_issues(gtk)
  File "/home/runner/work/threat-broadcast-1/threat-broadcast-1/src/utils/_git.py", line 43, in query_issues
    data = client.execute(
  File "/opt/hostedtoolcache/Python/3.8.12/x64/lib/python3.8/site-packages/python_graphql_client/graphql_client.py", line 53, in execute
    result.raise_for_status()
  File "/opt/hostedtoolcache/Python/3.8.12/x64/lib/python3.8/site-packages/requests/models.py", line 940, in raise_for_status
    raise HTTPError(http_error_msg, response=self)
requests.exceptions.HTTPError: 401 Client Error: Unauthorized for url: https://api.github.com/graphql
2022-05-01 07:56:41 [ERROR] : 获取 Issue 的邮箱失败（国内 GraphQL 接口不稳定）
Traceback (most recent call last):
  File "/home/runner/work/threat-broadcast-1/threat-broadcast-1/src/notice/mail.py", line 110, in load_issue_receivers
    issues = _git.query_issues(gtk)
  File "/home/runner/work/threat-broadcast-1/threat-broadcast-1/src/utils/_git.py", line 43, in query_issues
    data = client.execute(
  File "/opt/hostedtoolcache/Python/3.8.12/x64/lib/python3.8/site-packages/python_graphql_client/graphql_client.py", line 53, in execute
    result.raise_for_status()
  File "/opt/hostedtoolcache/Python/3.8.12/x64/lib/python3.8/site-packages/requests/models.py", line 940, in raise_for_status
    raise HTTPError(http_error_msg, response=self)
requests.exceptions.HTTPError: 401 Client Error: Unauthorized for url: https://api.github.com/graphql
2022-05-01 07:56:41 [ERROR] : Traceback (most recent call last):
  File "/home/runner/work/threat-broadcast-1/threat-broadcast-1/src/notice/mail.py", line 110, in load_issue_receivers
    issues = _git.query_issues(gtk)
  File "/home/runner/work/threat-broadcast-1/threat-broadcast-1/src/utils/_git.py", line 43, in query_issues
    data = client.execute(
  File "/opt/hostedtoolcache/Python/3.8.12/x64/lib/python3.8/site-packages/python_graphql_client/graphql_client.py", line 53, in execute
    result.raise_for_status()
  File "/opt/hostedtoolcache/Python/3.8.12/x64/lib/python3.8/site-packages/requests/models.py", line 940, in raise_for_status
    raise HTTPError(http_error_msg, response=self)
requests.exceptions.HTTPError: 401 Client Error: Unauthorized for url: https://api.github.com/graphql
Traceback (most recent call last):
  File "/home/runner/work/threat-broadcast-1/threat-broadcast-1/src/notice/mail.py", line 110, in load_issue_receivers
    issues = _git.query_issues(gtk)
  File "/home/runner/work/threat-broadcast-1/threat-broadcast-1/src/utils/_git.py", line 43, in query_issues
    data = client.execute(
  File "/opt/hostedtoolcache/Python/3.8.12/x64/lib/python3.8/site-packages/python_graphql_client/graphql_client.py", line 53, in execute
    result.raise_for_status()
  File "/opt/hostedtoolcache/Python/3.8.12/x64/lib/python3.8/site-packages/requests/models.py", line 940, in raise_for_status
    raise HTTPError(http_error_msg, response=self)
requests.exceptions.HTTPError: 401 Client Error: Unauthorized for url: https://api.github.com/graphql
2022-05-01 08:27:34 [ERROR] : 获取 Issue 的邮箱失败（国内 GraphQL 接口不稳定）
Traceback (most recent call last):
  File "/home/runner/work/threat-broadcast-1/threat-broadcast-1/src/notice/mail.py", line 110, in load_issue_receivers
    issues = _git.query_issues(gtk)
  File "/home/runner/work/threat-broadcast-1/threat-broadcast-1/src/utils/_git.py", line 43, in query_issues
    data = client.execute(
  File "/opt/hostedtoolcache/Python/3.8.12/x64/lib/python3.8/site-packages/python_graphql_client/graphql_client.py", line 53, in execute
    result.raise_for_status()
  File "/opt/hostedtoolcache/Python/3.8.12/x64/lib/python3.8/site-packages/requests/models.py", line 940, in raise_for_status
    raise HTTPError(http_error_msg, response=self)
requests.exceptions.HTTPError: 401 Client Error: Unauthorized for url: https://api.github.com/graphql
2022-05-01 08:27:34 [ERROR] : Traceback (most recent call last):
  File "/home/runner/work/threat-broadcast-1/threat-broadcast-1/src/notice/mail.py", line 110, in load_issue_receivers
    issues = _git.query_issues(gtk)
  File "/home/runner/work/threat-broadcast-1/threat-broadcast-1/src/utils/_git.py", line 43, in query_issues
    data = client.execute(
  File "/opt/hostedtoolcache/Python/3.8.12/x64/lib/python3.8/site-packages/python_graphql_client/graphql_client.py", line 53, in execute
    result.raise_for_status()
  File "/opt/hostedtoolcache/Python/3.8.12/x64/lib/python3.8/site-packages/requests/models.py", line 940, in raise_for_status
    raise HTTPError(http_error_msg, response=self)
requests.exceptions.HTTPError: 401 Client Error: Unauthorized for url: https://api.github.com/graphql
Traceback (most recent call last):
  File "/home/runner/work/threat-broadcast-1/threat-broadcast-1/src/notice/mail.py", line 110, in load_issue_receivers
    issues = _git.query_issues(gtk)
  File "/home/runner/work/threat-broadcast-1/threat-broadcast-1/src/utils/_git.py", line 43, in query_issues
    data = client.execute(
  File "/opt/hostedtoolcache/Python/3.8.12/x64/lib/python3.8/site-packages/python_graphql_client/graphql_client.py", line 53, in execute
    result.raise_for_status()
  File "/opt/hostedtoolcache/Python/3.8.12/x64/lib/python3.8/site-packages/requests/models.py", line 940, in raise_for_status
    raise HTTPError(http_error_msg, response=self)
requests.exceptions.HTTPError: 401 Client Error: Unauthorized for url: https://api.github.com/graphql
2022-05-01 08:47:01 [ERROR] : 获取 Issue 的邮箱失败（国内 GraphQL 接口不稳定）
Traceback (most recent call last):
  File "/home/runner/work/threat-broadcast-1/threat-broadcast-1/src/notice/mail.py", line 110, in load_issue_receivers
    issues = _git.query_issues(gtk)
  File "/home/runner/work/threat-broadcast-1/threat-broadcast-1/src/utils/_git.py", line 43, in query_issues
    data = client.execute(
  File "/opt/hostedtoolcache/Python/3.8.12/x64/lib/python3.8/site-packages/python_graphql_client/graphql_client.py", line 53, in execute
    result.raise_for_status()
  File "/opt/hostedtoolcache/Python/3.8.12/x64/lib/python3.8/site-packages/requests/models.py", line 940, in raise_for_status
    raise HTTPError(http_error_msg, response=self)
requests.exceptions.HTTPError: 401 Client Error: Unauthorized for url: https://api.github.com/graphql
2022-05-01 08:47:01 [ERROR] : Traceback (most recent call last):
  File "/home/runner/work/threat-broadcast-1/threat-broadcast-1/src/notice/mail.py", line 110, in load_issue_receivers
    issues = _git.query_issues(gtk)
  File "/home/runner/work/threat-broadcast-1/threat-broadcast-1/src/utils/_git.py", line 43, in query_issues
    data = client.execute(
  File "/opt/hostedtoolcache/Python/3.8.12/x64/lib/python3.8/site-packages/python_graphql_client/graphql_client.py", line 53, in execute
    result.raise_for_status()
  File "/opt/hostedtoolcache/Python/3.8.12/x64/lib/python3.8/site-packages/requests/models.py", line 940, in raise_for_status
    raise HTTPError(http_error_msg, response=self)
requests.exceptions.HTTPError: 401 Client Error: Unauthorized for url: https://api.github.com/graphql
Traceback (most recent call last):
  File "/home/runner/work/threat-broadcast-1/threat-broadcast-1/src/notice/mail.py", line 110, in load_issue_receivers
    issues = _git.query_issues(gtk)
  File "/home/runner/work/threat-broadcast-1/threat-broadcast-1/src/utils/_git.py", line 43, in query_issues
    data = client.execute(
  File "/opt/hostedtoolcache/Python/3.8.12/x64/lib/python3.8/site-packages/python_graphql_client/graphql_client.py", line 53, in execute
    result.raise_for_status()
  File "/opt/hostedtoolcache/Python/3.8.12/x64/lib/python3.8/site-packages/requests/models.py", line 940, in raise_for_status
    raise HTTPError(http_error_msg, response=self)
requests.exceptions.HTTPError: 401 Client Error: Unauthorized for url: https://api.github.com/graphql
2022-05-01 08:59:22 [ERROR] : 获取 Issue 的邮箱失败（国内 GraphQL 接口不稳定）
Traceback (most recent call last):
  File "/home/runner/work/threat-broadcast-1/threat-broadcast-1/src/notice/mail.py", line 110, in load_issue_receivers
    issues = _git.query_issues(gtk)
  File "/home/runner/work/threat-broadcast-1/threat-broadcast-1/src/utils/_git.py", line 43, in query_issues
    data = client.execute(
  File "/opt/hostedtoolcache/Python/3.8.12/x64/lib/python3.8/site-packages/python_graphql_client/graphql_client.py", line 53, in execute
    result.raise_for_status()
  File "/opt/hostedtoolcache/Python/3.8.12/x64/lib/python3.8/site-packages/requests/models.py", line 940, in raise_for_status
    raise HTTPError(http_error_msg, response=self)
requests.exceptions.HTTPError: 401 Client Error: Unauthorized for url: https://api.github.com/graphql
2022-05-01 08:59:22 [ERROR] : Traceback (most recent call last):
  File "/home/runner/work/threat-broadcast-1/threat-broadcast-1/src/notice/mail.py", line 110, in load_issue_receivers
    issues = _git.query_issues(gtk)
  File "/home/runner/work/threat-broadcast-1/threat-broadcast-1/src/utils/_git.py", line 43, in query_issues
    data = client.execute(
  File "/opt/hostedtoolcache/Python/3.8.12/x64/lib/python3.8/site-packages/python_graphql_client/graphql_client.py", line 53, in execute
    result.raise_for_status()
  File "/opt/hostedtoolcache/Python/3.8.12/x64/lib/python3.8/site-packages/requests/models.py", line 940, in raise_for_status
    raise HTTPError(http_error_msg, response=self)
requests.exceptions.HTTPError: 401 Client Error: Unauthorized for url: https://api.github.com/graphql
Traceback (most recent call last):
  File "/home/runner/work/threat-broadcast-1/threat-broadcast-1/src/notice/mail.py", line 110, in load_issue_receivers
    issues = _git.query_issues(gtk)
  File "/home/runner/work/threat-broadcast-1/threat-broadcast-1/src/utils/_git.py", line 43, in query_issues
    data = client.execute(
  File "/opt/hostedtoolcache/Python/3.8.12/x64/lib/python3.8/site-packages/python_graphql_client/graphql_client.py", line 53, in execute
    result.raise_for_status()
  File "/opt/hostedtoolcache/Python/3.8.12/x64/lib/python3.8/site-packages/requests/models.py", line 940, in raise_for_status
    raise HTTPError(http_error_msg, response=self)
requests.exceptions.HTTPError: 401 Client Error: Unauthorized for url: https://api.github.com/graphql
2022-05-01 09:25:52 [ERROR] : 获取 Issue 的邮箱失败（国内 GraphQL 接口不稳定）
Traceback (most recent call last):
  File "/home/runner/work/threat-broadcast-1/threat-broadcast-1/src/notice/mail.py", line 110, in load_issue_receivers
    issues = _git.query_issues(gtk)
  File "/home/runner/work/threat-broadcast-1/threat-broadcast-1/src/utils/_git.py", line 43, in query_issues
    data = client.execute(
  File "/opt/hostedtoolcache/Python/3.8.12/x64/lib/python3.8/site-packages/python_graphql_client/graphql_client.py", line 53, in execute
    result.raise_for_status()
  File "/opt/hostedtoolcache/Python/3.8.12/x64/lib/python3.8/site-packages/requests/models.py", line 940, in raise_for_status
    raise HTTPError(http_error_msg, response=self)
requests.exceptions.HTTPError: 401 Client Error: Unauthorized for url: https://api.github.com/graphql
2022-05-01 09:25:52 [ERROR] : Traceback (most recent call last):
  File "/home/runner/work/threat-broadcast-1/threat-broadcast-1/src/notice/mail.py", line 110, in load_issue_receivers
    issues = _git.query_issues(gtk)
  File "/home/runner/work/threat-broadcast-1/threat-broadcast-1/src/utils/_git.py", line 43, in query_issues
    data = client.execute(
  File "/opt/hostedtoolcache/Python/3.8.12/x64/lib/python3.8/site-packages/python_graphql_client/graphql_client.py", line 53, in execute
    result.raise_for_status()
  File "/opt/hostedtoolcache/Python/3.8.12/x64/lib/python3.8/site-packages/requests/models.py", line 940, in raise_for_status
    raise HTTPError(http_error_msg, response=self)
requests.exceptions.HTTPError: 401 Client Error: Unauthorized for url: https://api.github.com/graphql
Traceback (most recent call last):
  File "/home/runner/work/threat-broadcast-1/threat-broadcast-1/src/notice/mail.py", line 110, in load_issue_receivers
    issues = _git.query_issues(gtk)
  File "/home/runner/work/threat-broadcast-1/threat-broadcast-1/src/utils/_git.py", line 43, in query_issues
    data = client.execute(
  File "/opt/hostedtoolcache/Python/3.8.12/x64/lib/python3.8/site-packages/python_graphql_client/graphql_client.py", line 53, in execute
    result.raise_for_status()
  File "/opt/hostedtoolcache/Python/3.8.12/x64/lib/python3.8/site-packages/requests/models.py", line 940, in raise_for_status
    raise HTTPError(http_error_msg, response=self)
requests.exceptions.HTTPError: 401 Client Error: Unauthorized for url: https://api.github.com/graphql
2022-05-01 09:42:28 [ERROR] : 获取 Issue 的邮箱失败（国内 GraphQL 接口不稳定）
Traceback (most recent call last):
  File "/home/runner/work/threat-broadcast-1/threat-broadcast-1/src/notice/mail.py", line 110, in load_issue_receivers
    issues = _git.query_issues(gtk)
  File "/home/runner/work/threat-broadcast-1/threat-broadcast-1/src/utils/_git.py", line 43, in query_issues
    data = client.execute(
  File "/opt/hostedtoolcache/Python/3.8.12/x64/lib/python3.8/site-packages/python_graphql_client/graphql_client.py", line 53, in execute
    result.raise_for_status()
  File "/opt/hostedtoolcache/Python/3.8.12/x64/lib/python3.8/site-packages/requests/models.py", line 940, in raise_for_status
    raise HTTPError(http_error_msg, response=self)
requests.exceptions.HTTPError: 401 Client Error: Unauthorized for url: https://api.github.com/graphql
2022-05-01 09:42:28 [ERROR] : Traceback (most recent call last):
  File "/home/runner/work/threat-broadcast-1/threat-broadcast-1/src/notice/mail.py", line 110, in load_issue_receivers
    issues = _git.query_issues(gtk)
  File "/home/runner/work/threat-broadcast-1/threat-broadcast-1/src/utils/_git.py", line 43, in query_issues
    data = client.execute(
  File "/opt/hostedtoolcache/Python/3.8.12/x64/lib/python3.8/site-packages/python_graphql_client/graphql_client.py", line 53, in execute
    result.raise_for_status()
  File "/opt/hostedtoolcache/Python/3.8.12/x64/lib/python3.8/site-packages/requests/models.py", line 940, in raise_for_status
    raise HTTPError(http_error_msg, response=self)
requests.exceptions.HTTPError: 401 Client Error: Unauthorized for url: https://api.github.com/graphql
Traceback (most recent call last):
  File "/home/runner/work/threat-broadcast-1/threat-broadcast-1/src/notice/mail.py", line 110, in load_issue_receivers
    issues = _git.query_issues(gtk)
  File "/home/runner/work/threat-broadcast-1/threat-broadcast-1/src/utils/_git.py", line 43, in query_issues
    data = client.execute(
  File "/opt/hostedtoolcache/Python/3.8.12/x64/lib/python3.8/site-packages/python_graphql_client/graphql_client.py", line 53, in execute
    result.raise_for_status()
  File "/opt/hostedtoolcache/Python/3.8.12/x64/lib/python3.8/site-packages/requests/models.py", line 940, in raise_for_status
    raise HTTPError(http_error_msg, response=self)
requests.exceptions.HTTPError: 401 Client Error: Unauthorized for url: https://api.github.com/graphql
2022-05-01 09:54:41 [ERROR] : 获取 Issue 的邮箱失败（国内 GraphQL 接口不稳定）
Traceback (most recent call last):
  File "/home/runner/work/threat-broadcast-1/threat-broadcast-1/src/notice/mail.py", line 110, in load_issue_receivers
    issues = _git.query_issues(gtk)
  File "/home/runner/work/threat-broadcast-1/threat-broadcast-1/src/utils/_git.py", line 43, in query_issues
    data = client.execute(
  File "/opt/hostedtoolcache/Python/3.8.12/x64/lib/python3.8/site-packages/python_graphql_client/graphql_client.py", line 53, in execute
    result.raise_for_status()
  File "/opt/hostedtoolcache/Python/3.8.12/x64/lib/python3.8/site-packages/requests/models.py", line 940, in raise_for_status
    raise HTTPError(http_error_msg, response=self)
requests.exceptions.HTTPError: 401 Client Error: Unauthorized for url: https://api.github.com/graphql
2022-05-01 09:54:41 [ERROR] : Traceback (most recent call last):
  File "/home/runner/work/threat-broadcast-1/threat-broadcast-1/src/notice/mail.py", line 110, in load_issue_receivers
    issues = _git.query_issues(gtk)
  File "/home/runner/work/threat-broadcast-1/threat-broadcast-1/src/utils/_git.py", line 43, in query_issues
    data = client.execute(
  File "/opt/hostedtoolcache/Python/3.8.12/x64/lib/python3.8/site-packages/python_graphql_client/graphql_client.py", line 53, in execute
    result.raise_for_status()
  File "/opt/hostedtoolcache/Python/3.8.12/x64/lib/python3.8/site-packages/requests/models.py", line 940, in raise_for_status
    raise HTTPError(http_error_msg, response=self)
requests.exceptions.HTTPError: 401 Client Error: Unauthorized for url: https://api.github.com/graphql
Traceback (most recent call last):
  File "/home/runner/work/threat-broadcast-1/threat-broadcast-1/src/notice/mail.py", line 110, in load_issue_receivers
    issues = _git.query_issues(gtk)
  File "/home/runner/work/threat-broadcast-1/threat-broadcast-1/src/utils/_git.py", line 43, in query_issues
    data = client.execute(
  File "/opt/hostedtoolcache/Python/3.8.12/x64/lib/python3.8/site-packages/python_graphql_client/graphql_client.py", line 53, in execute
    result.raise_for_status()
  File "/opt/hostedtoolcache/Python/3.8.12/x64/lib/python3.8/site-packages/requests/models.py", line 940, in raise_for_status
    raise HTTPError(http_error_msg, response=self)
requests.exceptions.HTTPError: 401 Client Error: Unauthorized for url: https://api.github.com/graphql
2022-05-01 10:20:37 [ERROR] : 获取 Issue 的邮箱失败（国内 GraphQL 接口不稳定）
Traceback (most recent call last):
  File "/home/runner/work/threat-broadcast-1/threat-broadcast-1/src/notice/mail.py", line 110, in load_issue_receivers
    issues = _git.query_issues(gtk)
  File "/home/runner/work/threat-broadcast-1/threat-broadcast-1/src/utils/_git.py", line 43, in query_issues
    data = client.execute(
  File "/opt/hostedtoolcache/Python/3.8.12/x64/lib/python3.8/site-packages/python_graphql_client/graphql_client.py", line 53, in execute
    result.raise_for_status()
  File "/opt/hostedtoolcache/Python/3.8.12/x64/lib/python3.8/site-packages/requests/models.py", line 940, in raise_for_status
    raise HTTPError(http_error_msg, response=self)
requests.exceptions.HTTPError: 401 Client Error: Unauthorized for url: https://api.github.com/graphql
2022-05-01 10:20:37 [ERROR] : Traceback (most recent call last):
  File "/home/runner/work/threat-broadcast-1/threat-broadcast-1/src/notice/mail.py", line 110, in load_issue_receivers
    issues = _git.query_issues(gtk)
  File "/home/runner/work/threat-broadcast-1/threat-broadcast-1/src/utils/_git.py", line 43, in query_issues
    data = client.execute(
  File "/opt/hostedtoolcache/Python/3.8.12/x64/lib/python3.8/site-packages/python_graphql_client/graphql_client.py", line 53, in execute
    result.raise_for_status()
  File "/opt/hostedtoolcache/Python/3.8.12/x64/lib/python3.8/site-packages/requests/models.py", line 940, in raise_for_status
    raise HTTPError(http_error_msg, response=self)
requests.exceptions.HTTPError: 401 Client Error: Unauthorized for url: https://api.github.com/graphql
Traceback (most recent call last):
  File "/home/runner/work/threat-broadcast-1/threat-broadcast-1/src/notice/mail.py", line 110, in load_issue_receivers
    issues = _git.query_issues(gtk)
  File "/home/runner/work/threat-broadcast-1/threat-broadcast-1/src/utils/_git.py", line 43, in query_issues
    data = client.execute(
  File "/opt/hostedtoolcache/Python/3.8.12/x64/lib/python3.8/site-packages/python_graphql_client/graphql_client.py", line 53, in execute
    result.raise_for_status()
  File "/opt/hostedtoolcache/Python/3.8.12/x64/lib/python3.8/site-packages/requests/models.py", line 940, in raise_for_status
    raise HTTPError(http_error_msg, response=self)
requests.exceptions.HTTPError: 401 Client Error: Unauthorized for url: https://api.github.com/graphql
2022-05-01 10:40:02 [ERROR] : 获取 Issue 的邮箱失败（国内 GraphQL 接口不稳定）
Traceback (most recent call last):
  File "/home/runner/work/threat-broadcast-1/threat-broadcast-1/src/notice/mail.py", line 110, in load_issue_receivers
    issues = _git.query_issues(gtk)
  File "/home/runner/work/threat-broadcast-1/threat-broadcast-1/src/utils/_git.py", line 43, in query_issues
    data = client.execute(
  File "/opt/hostedtoolcache/Python/3.8.12/x64/lib/python3.8/site-packages/python_graphql_client/graphql_client.py", line 53, in execute
    result.raise_for_status()
  File "/opt/hostedtoolcache/Python/3.8.12/x64/lib/python3.8/site-packages/requests/models.py", line 940, in raise_for_status
    raise HTTPError(http_error_msg, response=self)
requests.exceptions.HTTPError: 401 Client Error: Unauthorized for url: https://api.github.com/graphql
2022-05-01 10:40:02 [ERROR] : Traceback (most recent call last):
  File "/home/runner/work/threat-broadcast-1/threat-broadcast-1/src/notice/mail.py", line 110, in load_issue_receivers
    issues = _git.query_issues(gtk)
  File "/home/runner/work/threat-broadcast-1/threat-broadcast-1/src/utils/_git.py", line 43, in query_issues
    data = client.execute(
  File "/opt/hostedtoolcache/Python/3.8.12/x64/lib/python3.8/site-packages/python_graphql_client/graphql_client.py", line 53, in execute
    result.raise_for_status()
  File "/opt/hostedtoolcache/Python/3.8.12/x64/lib/python3.8/site-packages/requests/models.py", line 940, in raise_for_status
    raise HTTPError(http_error_msg, response=self)
requests.exceptions.HTTPError: 401 Client Error: Unauthorized for url: https://api.github.com/graphql
Traceback (most recent call last):
  File "/home/runner/work/threat-broadcast-1/threat-broadcast-1/src/notice/mail.py", line 110, in load_issue_receivers
    issues = _git.query_issues(gtk)
  File "/home/runner/work/threat-broadcast-1/threat-broadcast-1/src/utils/_git.py", line 43, in query_issues
    data = client.execute(
  File "/opt/hostedtoolcache/Python/3.8.12/x64/lib/python3.8/site-packages/python_graphql_client/graphql_client.py", line 53, in execute
    result.raise_for_status()
  File "/opt/hostedtoolcache/Python/3.8.12/x64/lib/python3.8/site-packages/requests/models.py", line 940, in raise_for_status
    raise HTTPError(http_error_msg, response=self)
requests.exceptions.HTTPError: 401 Client Error: Unauthorized for url: https://api.github.com/graphql
2022-05-01 10:52:22 [ERROR] : 获取 Issue 的邮箱失败（国内 GraphQL 接口不稳定）
Traceback (most recent call last):
  File "/home/runner/work/threat-broadcast-1/threat-broadcast-1/src/notice/mail.py", line 110, in load_issue_receivers
    issues = _git.query_issues(gtk)
  File "/home/runner/work/threat-broadcast-1/threat-broadcast-1/src/utils/_git.py", line 43, in query_issues
    data = client.execute(
  File "/opt/hostedtoolcache/Python/3.8.12/x64/lib/python3.8/site-packages/python_graphql_client/graphql_client.py", line 53, in execute
    result.raise_for_status()
  File "/opt/hostedtoolcache/Python/3.8.12/x64/lib/python3.8/site-packages/requests/models.py", line 940, in raise_for_status
    raise HTTPError(http_error_msg, response=self)
requests.exceptions.HTTPError: 401 Client Error: Unauthorized for url: https://api.github.com/graphql
2022-05-01 10:52:22 [ERROR] : Traceback (most recent call last):
  File "/home/runner/work/threat-broadcast-1/threat-broadcast-1/src/notice/mail.py", line 110, in load_issue_receivers
    issues = _git.query_issues(gtk)
  File "/home/runner/work/threat-broadcast-1/threat-broadcast-1/src/utils/_git.py", line 43, in query_issues
    data = client.execute(
  File "/opt/hostedtoolcache/Python/3.8.12/x64/lib/python3.8/site-packages/python_graphql_client/graphql_client.py", line 53, in execute
    result.raise_for_status()
  File "/opt/hostedtoolcache/Python/3.8.12/x64/lib/python3.8/site-packages/requests/models.py", line 940, in raise_for_status
    raise HTTPError(http_error_msg, response=self)
requests.exceptions.HTTPError: 401 Client Error: Unauthorized for url: https://api.github.com/graphql
Traceback (most recent call last):
  File "/home/runner/work/threat-broadcast-1/threat-broadcast-1/src/notice/mail.py", line 110, in load_issue_receivers
    issues = _git.query_issues(gtk)
  File "/home/runner/work/threat-broadcast-1/threat-broadcast-1/src/utils/_git.py", line 43, in query_issues
    data = client.execute(
  File "/opt/hostedtoolcache/Python/3.8.12/x64/lib/python3.8/site-packages/python_graphql_client/graphql_client.py", line 53, in execute
    result.raise_for_status()
  File "/opt/hostedtoolcache/Python/3.8.12/x64/lib/python3.8/site-packages/requests/models.py", line 940, in raise_for_status
    raise HTTPError(http_error_msg, response=self)
requests.exceptions.HTTPError: 401 Client Error: Unauthorized for url: https://api.github.com/graphql
2022-05-01 11:13:15 [ERROR] : 获取 Issue 的邮箱失败（国内 GraphQL 接口不稳定）
Traceback (most recent call last):
  File "/home/runner/work/threat-broadcast-1/threat-broadcast-1/src/notice/mail.py", line 110, in load_issue_receivers
    issues = _git.query_issues(gtk)
  File "/home/runner/work/threat-broadcast-1/threat-broadcast-1/src/utils/_git.py", line 43, in query_issues
    data = client.execute(
  File "/opt/hostedtoolcache/Python/3.8.12/x64/lib/python3.8/site-packages/python_graphql_client/graphql_client.py", line 53, in execute
    result.raise_for_status()
  File "/opt/hostedtoolcache/Python/3.8.12/x64/lib/python3.8/site-packages/requests/models.py", line 940, in raise_for_status
    raise HTTPError(http_error_msg, response=self)
requests.exceptions.HTTPError: 401 Client Error: Unauthorized for url: https://api.github.com/graphql
2022-05-01 11:13:15 [ERROR] : Traceback (most recent call last):
  File "/home/runner/work/threat-broadcast-1/threat-broadcast-1/src/notice/mail.py", line 110, in load_issue_receivers
    issues = _git.query_issues(gtk)
  File "/home/runner/work/threat-broadcast-1/threat-broadcast-1/src/utils/_git.py", line 43, in query_issues
    data = client.execute(
  File "/opt/hostedtoolcache/Python/3.8.12/x64/lib/python3.8/site-packages/python_graphql_client/graphql_client.py", line 53, in execute
    result.raise_for_status()
  File "/opt/hostedtoolcache/Python/3.8.12/x64/lib/python3.8/site-packages/requests/models.py", line 940, in raise_for_status
    raise HTTPError(http_error_msg, response=self)
requests.exceptions.HTTPError: 401 Client Error: Unauthorized for url: https://api.github.com/graphql
Traceback (most recent call last):
  File "/home/runner/work/threat-broadcast-1/threat-broadcast-1/src/notice/mail.py", line 110, in load_issue_receivers
    issues = _git.query_issues(gtk)
  File "/home/runner/work/threat-broadcast-1/threat-broadcast-1/src/utils/_git.py", line 43, in query_issues
    data = client.execute(
  File "/opt/hostedtoolcache/Python/3.8.12/x64/lib/python3.8/site-packages/python_graphql_client/graphql_client.py", line 53, in execute
    result.raise_for_status()
  File "/opt/hostedtoolcache/Python/3.8.12/x64/lib/python3.8/site-packages/requests/models.py", line 940, in raise_for_status
    raise HTTPError(http_error_msg, response=self)
requests.exceptions.HTTPError: 401 Client Error: Unauthorized for url: https://api.github.com/graphql
2022-05-01 11:28:51 [ERROR] : 获取 Issue 的邮箱失败（国内 GraphQL 接口不稳定）
Traceback (most recent call last):
  File "/home/runner/work/threat-broadcast-1/threat-broadcast-1/src/notice/mail.py", line 110, in load_issue_receivers
    issues = _git.query_issues(gtk)
  File "/home/runner/work/threat-broadcast-1/threat-broadcast-1/src/utils/_git.py", line 43, in query_issues
    data = client.execute(
  File "/opt/hostedtoolcache/Python/3.8.12/x64/lib/python3.8/site-packages/python_graphql_client/graphql_client.py", line 53, in execute
    result.raise_for_status()
  File "/opt/hostedtoolcache/Python/3.8.12/x64/lib/python3.8/site-packages/requests/models.py", line 940, in raise_for_status
    raise HTTPError(http_error_msg, response=self)
requests.exceptions.HTTPError: 401 Client Error: Unauthorized for url: https://api.github.com/graphql
2022-05-01 11:28:51 [ERROR] : Traceback (most recent call last):
  File "/home/runner/work/threat-broadcast-1/threat-broadcast-1/src/notice/mail.py", line 110, in load_issue_receivers
    issues = _git.query_issues(gtk)
  File "/home/runner/work/threat-broadcast-1/threat-broadcast-1/src/utils/_git.py", line 43, in query_issues
    data = client.execute(
  File "/opt/hostedtoolcache/Python/3.8.12/x64/lib/python3.8/site-packages/python_graphql_client/graphql_client.py", line 53, in execute
    result.raise_for_status()
  File "/opt/hostedtoolcache/Python/3.8.12/x64/lib/python3.8/site-packages/requests/models.py", line 940, in raise_for_status
    raise HTTPError(http_error_msg, response=self)
requests.exceptions.HTTPError: 401 Client Error: Unauthorized for url: https://api.github.com/graphql
Traceback (most recent call last):
  File "/home/runner/work/threat-broadcast-1/threat-broadcast-1/src/notice/mail.py", line 110, in load_issue_receivers
    issues = _git.query_issues(gtk)
  File "/home/runner/work/threat-broadcast-1/threat-broadcast-1/src/utils/_git.py", line 43, in query_issues
    data = client.execute(
  File "/opt/hostedtoolcache/Python/3.8.12/x64/lib/python3.8/site-packages/python_graphql_client/graphql_client.py", line 53, in execute
    result.raise_for_status()
  File "/opt/hostedtoolcache/Python/3.8.12/x64/lib/python3.8/site-packages/requests/models.py", line 940, in raise_for_status
    raise HTTPError(http_error_msg, response=self)
requests.exceptions.HTTPError: 401 Client Error: Unauthorized for url: https://api.github.com/graphql
2022-05-01 11:53:31 [ERROR] : 获取 Issue 的邮箱失败（国内 GraphQL 接口不稳定）
Traceback (most recent call last):
  File "/home/runner/work/threat-broadcast-1/threat-broadcast-1/src/notice/mail.py", line 110, in load_issue_receivers
    issues = _git.query_issues(gtk)
  File "/home/runner/work/threat-broadcast-1/threat-broadcast-1/src/utils/_git.py", line 43, in query_issues
    data = client.execute(
  File "/opt/hostedtoolcache/Python/3.8.12/x64/lib/python3.8/site-packages/python_graphql_client/graphql_client.py", line 53, in execute
    result.raise_for_status()
  File "/opt/hostedtoolcache/Python/3.8.12/x64/lib/python3.8/site-packages/requests/models.py", line 940, in raise_for_status
    raise HTTPError(http_error_msg, response=self)
requests.exceptions.HTTPError: 401 Client Error: Unauthorized for url: https://api.github.com/graphql
2022-05-01 11:53:31 [ERROR] : Traceback (most recent call last):
  File "/home/runner/work/threat-broadcast-1/threat-broadcast-1/src/notice/mail.py", line 110, in load_issue_receivers
    issues = _git.query_issues(gtk)
  File "/home/runner/work/threat-broadcast-1/threat-broadcast-1/src/utils/_git.py", line 43, in query_issues
    data = client.execute(
  File "/opt/hostedtoolcache/Python/3.8.12/x64/lib/python3.8/site-packages/python_graphql_client/graphql_client.py", line 53, in execute
    result.raise_for_status()
  File "/opt/hostedtoolcache/Python/3.8.12/x64/lib/python3.8/site-packages/requests/models.py", line 940, in raise_for_status
    raise HTTPError(http_error_msg, response=self)
requests.exceptions.HTTPError: 401 Client Error: Unauthorized for url: https://api.github.com/graphql
Traceback (most recent call last):
  File "/home/runner/work/threat-broadcast-1/threat-broadcast-1/src/notice/mail.py", line 110, in load_issue_receivers
    issues = _git.query_issues(gtk)
  File "/home/runner/work/threat-broadcast-1/threat-broadcast-1/src/utils/_git.py", line 43, in query_issues
    data = client.execute(
  File "/opt/hostedtoolcache/Python/3.8.12/x64/lib/python3.8/site-packages/python_graphql_client/graphql_client.py", line 53, in execute
    result.raise_for_status()
  File "/opt/hostedtoolcache/Python/3.8.12/x64/lib/python3.8/site-packages/requests/models.py", line 940, in raise_for_status
    raise HTTPError(http_error_msg, response=self)
requests.exceptions.HTTPError: 401 Client Error: Unauthorized for url: https://api.github.com/graphql
