2022-03-19 00:25:30 [INFO] : ++++++++++++++++++++++++++++++++++++++++++++
2022-03-19 00:25:30 [INFO] : 正在获取 [数字观星POC++] 威胁情报...
2022-03-19 00:25:32 [INFO] : 得到 [数字观星POC++] 最新威胁情报 [0] 条
2022-03-19 00:25:32 [INFO] : --------------------------------------------
2022-03-19 00:25:32 [INFO] : ++++++++++++++++++++++++++++++++++++++++++++
2022-03-19 00:25:32 [INFO] : 正在获取 [阿里云] 威胁情报...
2022-03-19 00:25:33 [INFO] : 得到 [阿里云] 最新威胁情报 [0] 条
2022-03-19 00:25:33 [INFO] : --------------------------------------------
2022-03-19 00:25:33 [INFO] : ++++++++++++++++++++++++++++++++++++++++++++
2022-03-19 00:25:33 [INFO] : 正在获取 [国家信息安全漏洞共享平台（CNVD）] 威胁情报...
2022-03-19 00:25:54 [INFO] : 得到 [国家信息安全漏洞共享平台（CNVD）] 最新威胁情报 [1] 条
2022-03-19 00:25:54 [INFO] : --------------------------------------------
2022-03-19 00:25:54 [INFO] : 
==============================================
[ TITLE ] Arista VEOS存在拒绝服务漏洞
[ TIME  ] 2022-03-19 00:25:34
[ CVE   ] CNVD-2022-16682
[ SRC   ] 国家信息安全漏洞共享平台（CNVD）
[ URL   ] https://www.cnvd.org.cn/flaw/show/CNVD-2022-16682
2022-03-19 00:25:54 [INFO] : ++++++++++++++++++++++++++++++++++++++++++++
2022-03-19 00:25:54 [INFO] : 正在获取 [国家信息安全漏洞库（CNNVD）] 威胁情报...
2022-03-19 00:26:08 [INFO] : 得到 [国家信息安全漏洞库（CNNVD）] 最新威胁情报 [0] 条
2022-03-19 00:26:08 [INFO] : --------------------------------------------
2022-03-19 00:26:08 [INFO] : ++++++++++++++++++++++++++++++++++++++++++++
2022-03-19 00:26:08 [INFO] : 正在获取 [360 网络安全响应中心] 威胁情报...
2022-03-19 00:26:10 [INFO] : 得到 [360 网络安全响应中心] 最新威胁情报 [0] 条
2022-03-19 00:26:10 [INFO] : --------------------------------------------
2022-03-19 00:26:10 [INFO] : ++++++++++++++++++++++++++++++++++++++++++++
2022-03-19 00:26:10 [INFO] : 正在获取 [美国国家漏洞数据库（NVD）] 威胁情报...
2022-03-19 00:26:11 [INFO] : 得到 [美国国家漏洞数据库（NVD）] 最新威胁情报 [4] 条
2022-03-19 00:26:11 [INFO] : --------------------------------------------
2022-03-19 00:26:11 [INFO] : 
==============================================
[ TITLE ] SPIP before 3.2.14 and 4.x before 4.0.5 allows remote authenticated editors to execute arbitrary code.
[ TIME  ] 2022-03-10 17:48:01 
[ CVE   ] CVE-2022-26846
[ SRC   ] 美国国家漏洞数据库（NVD）
[ URL   ] https://web.nvd.nist.gov/view/vuln/detail?vulnId=CVE-2022-26846
2022-03-19 00:26:11 [INFO] : 
==============================================
[ TITLE ] Veritas System Recovery (VSR) 18 and 21 stores a network destination password in the Windows registry during configuration of the backup configuration. This could allow a Windows user (who has sufficient privileges) to access a network file system that they were not authorized to access.
[ TIME  ] 2022-03-10 17:47:58 
[ CVE   ] CVE-2022-26778
[ SRC   ] 美国国家漏洞数据库（NVD）
[ URL   ] https://web.nvd.nist.gov/view/vuln/detail?vulnId=CVE-2022-26778
2022-03-19 00:26:11 [INFO] : 
==============================================
[ TITLE ] An XML Entity Expansion (XEE) issue was discovered in Tryton Application Platform (Server) 5.x through 5.0.45, 6.x through 6.0.15, and 6.1.x and 6.2.x through 6.2.5, and Tryton Application Platform (Command Line Client (proteus)) 5.x through 5.0.11, 6.x through 6.0.4, and 6.1.x and 6.2.x through 6.2.1. An unauthenticated user can send a crafted XML-RPC message to consume all the resources of the server.
[ TIME  ] 2022-03-10 17:47:52 
[ CVE   ] CVE-2022-26662
[ SRC   ] 美国国家漏洞数据库（NVD）
[ URL   ] https://web.nvd.nist.gov/view/vuln/detail?vulnId=CVE-2022-26662
2022-03-19 00:26:11 [INFO] : 
==============================================
[ TITLE ] An XXE issue was discovered in Tryton Application Platform (Server) 5.x through 5.0.45, 6.x through 6.0.15, and 6.1.x and 6.2.x through 6.2.5, and Tryton Application Platform (Command Line Client (proteus)) 5.x through 5.0.11, 6.x through 6.0.4, and 6.1.x and 6.2.x through 6.2.1. An authenticated user can make the server parse a crafted XML SEPA file to access arbitrary files on the system.
[ TIME  ] 2022-03-10 17:47:52 
[ CVE   ] CVE-2022-26661
[ SRC   ] 美国国家漏洞数据库（NVD）
[ URL   ] https://web.nvd.nist.gov/view/vuln/detail?vulnId=CVE-2022-26661
2022-03-19 00:26:11 [INFO] : ++++++++++++++++++++++++++++++++++++++++++++
2022-03-19 00:26:11 [INFO] : 正在获取 [信息安全漏洞门户] 威胁情报...
2022-03-19 00:26:11 [INFO] : 得到 [信息安全漏洞门户] 最新威胁情报 [0] 条
2022-03-19 00:26:11 [INFO] : --------------------------------------------
2022-03-19 00:26:11 [INFO] : ++++++++++++++++++++++++++++++++++++++++++++
2022-03-19 00:26:11 [INFO] : 正在获取 [绿盟] 威胁情报...
2022-03-19 00:26:12 [INFO] : 得到 [绿盟] 最新威胁情报 [0] 条
2022-03-19 00:26:12 [INFO] : --------------------------------------------
2022-03-19 00:26:12 [INFO] : ++++++++++++++++++++++++++++++++++++++++++++
2022-03-19 00:26:12 [INFO] : 正在获取 [奇安信] 威胁情报...
2022-03-19 00:26:12 [INFO] : 得到 [奇安信] 最新威胁情报 [0] 条
2022-03-19 00:26:12 [INFO] : --------------------------------------------
2022-03-19 00:26:12 [INFO] : ++++++++++++++++++++++++++++++++++++++++++++
2022-03-19 00:26:12 [INFO] : 正在获取 [红后] 威胁情报...
2022-03-19 00:26:13 [INFO] : 得到 [红后] 最新威胁情报 [0] 条
2022-03-19 00:26:13 [INFO] : --------------------------------------------
2022-03-19 00:26:13 [INFO] : ++++++++++++++++++++++++++++++++++++++++++++
2022-03-19 00:26:13 [INFO] : 正在获取 [斗象] 威胁情报...
2022-03-19 00:26:15 [INFO] : 得到 [斗象] 最新威胁情报 [0] 条
2022-03-19 00:26:15 [INFO] : --------------------------------------------
2022-03-19 00:26:15 [INFO] : ++++++++++++++++++++++++++++++++++++++++++++
2022-03-19 00:26:15 [INFO] : 正在获取 [Tenable (Nessus)] 威胁情报...
2022-03-19 00:26:16 [INFO] : 得到 [Tenable (Nessus)] 最新威胁情报 [2] 条
2022-03-19 00:26:16 [INFO] : --------------------------------------------
2022-03-19 00:26:16 [INFO] : 
==============================================
[ TITLE ] Automotive Grade Linux Kooky Koi 11.0.0, 11.0.1, 11.0.2, 11.0.3, 11.0.4, and 11.0.5 is affected by Incorrect Access Control in usr/bin/afb-daemon. To exploit the vulnerability, an attacker should send a well-crafted HTTP (or WebSocket) request to the socket listened by the afb-daemon process. No credentials nor user interactions are required.
[ TIME  ] 2022-03-18 12:15:00
[ CVE   ] CVE-2022-24595
[ SRC   ] Tenable (Nessus)
[ URL   ] https://www.tenable.com/cve/CVE-2022-24595
2022-03-19 00:26:16 [INFO] : 
==============================================
[ TITLE ] Memory leak in icmp6 implementation in Linux Kernel 5.13+ allows a remote attacker to DoS a host by making it go out-of-memory via icmp6 packets of type 130 or 131. We recommend upgrading past commit 2d3916f3189172d5c69d33065c3c21119fe539fc.
[ TIME  ] 2022-03-18 12:15:00
[ CVE   ] CVE-2022-0742
[ SRC   ] Tenable (Nessus)
[ URL   ] https://www.tenable.com/cve/CVE-2022-0742
2022-03-19 00:26:16 [INFO] : [邮件] 正在推送威胁情报...
2022-03-19 00:26:16 [INFO] : [邮件] 收件人清单： ['207176126@qq.com']
2022-03-19 00:26:17 [INFO] : [邮件] 推送威胁情报成功
2022-03-19 00:26:17 [INFO] : 正在提交变更...
2022-03-19 00:26:20 [ERROR] : 提交变更失败
Traceback (most recent call last):
  File "/root/project/threat-broadcast-1/src/utils/_git.py", line 26, in auto_commit
    repo.git.push()
  File "/usr/local/python3/lib/python3.8/site-packages/git/cmd.py", line 542, in <lambda>
    return lambda *args, **kwargs: self._call_process(name, *args, **kwargs)
  File "/usr/local/python3/lib/python3.8/site-packages/git/cmd.py", line 1005, in _call_process
    return self.execute(call, **exec_kwargs)
  File "/usr/local/python3/lib/python3.8/site-packages/git/cmd.py", line 822, in execute
    raise GitCommandError(command, status, stderr_value, stdout_value)
git.exc.GitCommandError: Cmd('git') failed due to: exit code(1)
  cmdline: git push
  stderr: 'To git@github.com:hkmayfly/threat-broadcast-1.git
 ! [rejected]        master -> master (fetch first)
error: failed to push some refs to 'git@github.com:hkmayfly/threat-broadcast-1.git'
hint: Updates were rejected because the remote contains work that you do
hint: not have locally. This is usually caused by another repository pushing
hint: to the same ref. You may want to first merge the remote changes (e.g.,
hint: 'git pull') before pushing again.
hint: See the 'Note about fast-forwards' in 'git push --help' for details.'
2022-03-19 00:26:20 [ERROR] : Traceback (most recent call last):
  File "/root/project/threat-broadcast-1/src/utils/_git.py", line 26, in auto_commit
    repo.git.push()
  File "/usr/local/python3/lib/python3.8/site-packages/git/cmd.py", line 542, in <lambda>
    return lambda *args, **kwargs: self._call_process(name, *args, **kwargs)
  File "/usr/local/python3/lib/python3.8/site-packages/git/cmd.py", line 1005, in _call_process
    return self.execute(call, **exec_kwargs)
  File "/usr/local/python3/lib/python3.8/site-packages/git/cmd.py", line 822, in execute
    raise GitCommandError(command, status, stderr_value, stdout_value)
git.exc.GitCommandError: Cmd('git') failed due to: exit code(1)
  cmdline: git push
  stderr: 'To git@github.com:hkmayfly/threat-broadcast-1.git
 ! [rejected]        master -> master (fetch first)
error: failed to push some refs to 'git@github.com:hkmayfly/threat-broadcast-1.git'
hint: Updates were rejected because the remote contains work that you do
hint: not have locally. This is usually caused by another repository pushing
hint: to the same ref. You may want to first merge the remote changes (e.g.,
hint: 'git pull') before pushing again.
hint: See the 'Note about fast-forwards' in 'git push --help' for details.'
Traceback (most recent call last):
  File "/root/project/threat-broadcast-1/src/utils/_git.py", line 26, in auto_commit
    repo.git.push()
  File "/usr/local/python3/lib/python3.8/site-packages/git/cmd.py", line 542, in <lambda>
    return lambda *args, **kwargs: self._call_process(name, *args, **kwargs)
  File "/usr/local/python3/lib/python3.8/site-packages/git/cmd.py", line 1005, in _call_process
    return self.execute(call, **exec_kwargs)
  File "/usr/local/python3/lib/python3.8/site-packages/git/cmd.py", line 822, in execute
    raise GitCommandError(command, status, stderr_value, stdout_value)
git.exc.GitCommandError: Cmd('git') failed due to: exit code(1)
  cmdline: git push
  stderr: 'To git@github.com:hkmayfly/threat-broadcast-1.git
 ! [rejected]        master -> master (fetch first)
error: failed to push some refs to 'git@github.com:hkmayfly/threat-broadcast-1.git'
hint: Updates were rejected because the remote contains work that you do
hint: not have locally. This is usually caused by another repository pushing
hint: to the same ref. You may want to first merge the remote changes (e.g.,
hint: 'git pull') before pushing again.
hint: See the 'Note about fast-forwards' in 'git push --help' for details.'
